Workbook

Sheet README
A1: SpaceX valuation — Excel companion to 'Valuing SpaceX: Cash Flows versus the Cost of Capital'
A2: Alexander F. Wagner, June 2026. Paper: ssrn.com/abstract=6918120. Code: github.com/alex-wagner-research/spacex-valuation
A4: Comments and corrections are very welcome (alexander.wagner@df.uzh.ch). This workbook was put
A5: together quickly around a live IPO; if something looks off, it may well be.
A7: Tabs:
A8: Inputs — every assumption, blue on yellow, with its source. Change these.
A9: DCF — the deterministic three-segment valuation as a classic year-by-year
A10: waterfall with a step-by-step terminal value (paper Section 4), plus the
A11: direct-to-cell underlying business.
A12: Options — the expansion claims by their closed forms, the Mars probability tree,
A13: and the imported abandonment option (paper Section 5).
A14: MonteCarlo — 1,000 live trials of the correlated segment model (paper Section 4.3):
... A28: Appendix B.

Sheet Inputs
A1: Inputs — change the blue cells; every tab updates
A2: Values in $M unless noted. Paper: ssrn.com/abstract=6918120 (Table 1, Appendix A).
A5: Segments (2025 figures from the prospectus; targets, margins, volatilities per paper Table 1)
A6: Launch: revenue 2025 | B6: 4086 | C6: Prospectus, segment results (FWP acc. 0001628280-26-041013)
A7: Launch: revenue target 2036 | B7: 40000 | C7: Damodaran, June 2026 valuation (paper Sec. 4)
A8: Launch: operating margin 2025 | B8: 0.3 | C8: Prospectus, segment results
A9: Launch: terminal margin | B9: 0.45 | C9: Comparables-disciplined (paper Sec. 4); xAI 25% is the boundary case
A10: Launch: sales-to-capital | B10: 3.5 | C10: Damodaran convention (paper Table 1)
A11: Launch: revenue volatility, initial | B11: 0.18 | C11: Calibrated so dispersion lies between the two published simulations (Table 1)
A12: Launch: revenue volatility, long run | B12: 0.08 | C12: Paper Table 1
A13: Starlink: revenue 2025 | B13: 11387 | C13: Prospectus, segment results (FWP acc. 0001628280-26-041013)
A14: Starlink: revenue target 2036 | B14: 120000 | C14: Damodaran, June 2026 valuation (paper Sec. 4)
A15: Starlink: operating margin 2025 | B15: 0.35 | C15: Prospectus, segment results
A16: Starlink: terminal margin | B16: 0.6 | C16: Comparables-disciplined (paper Sec. 4); xAI 25% is the boundary case
A17: Starlink: sales-to-capital | B17: 4 | C17: Damodaran convention (paper Table 1)
... A26: xAI: revenue volatility, long run | B26: 0.15 | C26: Paper Table 1
A28: Firm-level
A29: Cost of capital (WACC) | B29: 0.0825 | C29: Damodaran bottom-up CAPM: business-weighted relevered betas (paper Sec. 4.2)
A30: Terminal growth | B30: 0.0456 | C30: Equals the June 2026 risk-free rate (Damodaran convention)
A31: Terminal ROIC | B31: 0.15 | C31: Paper Table 1; sets perpetuity reinvestment g/ROIC
A32: Tax rate, current effective | B32: 0.1 | C32: Prospectus financials
A33: Tax rate, marginal | B33: 0.25 | C33: Paper Table 1
A34: Cash | B34: 24747 | C34: Prospectus balance sheet
A35: Debt | B35: 22896 | C35: Prospectus balance sheet
A36: IPO proceeds | B36: 75000 | C36: Offering: 555.6M shares at $135
A37: Shares outstanding (M) | B37: 13091 | C37: 12,535M pre-offering + 556M new; CEO unvested award excluded (paper fn.)
A38: Common-factor correlation rho | B38: 0.3 | C38: Paper Table 1 (segments share one demand factor)
A39: Volatility decay kappa | B39: 0.2 | C39: Paper Appendix A.1 (uncertainty resolves over time)
A41: Expansion claims (paper Sec. 5.1, Appendix A.2)
A42: DTC: 2025 revenue | B42: 500 | C42: DTC underlying segment (Appendix A.2)
A43: DTC: revenue target 2036 | B43: 15000 | C43: Between D2D forecasts of roughly $3-12B (2030) and ~$100B long-run
A44: DTC: margin 2025 | B44: -0.2 | C44: Appendix A.2
A45: DTC: terminal margin | B45: 0.55 | C45: Appendix A.2
A46: DTC: sales-to-capital | B46: 4 | C46: Appendix A.2
A47: DTC: investment I | B47: 12000 | C47: Next-generation constellation cost (paper Sec. 5.1)
A48: DTC: gate year tau | B48: 4 | C48: Appendix A.2
A49: DTC: volatility sigma | B49: 0.55 | C49: Appendix A.2
A50: Starship: underlying V | B50: 110000 | C50: Capitalized launch pool $14-41B/yr: CRS IF12900, NASA OIG (App. A.3)
A51: Starship: investment I | B51: 30000 | C51: Over $15B spent plus $10-25B infrastructure (App. A.3)
A52: Starship: gate year tau | B52: 5 | C52: Appendix A.2
...

Sheet DCF
A1: Deterministic DCF — paper Section 4, Appendix A.1 (all values $M)
A2: The classic waterfall, year by year: revenue, margin, EBIT, taxes, reinvestment, FCFF, discounting; then the terminal value step by step. Margins and the tax rate ramp linearly; taxes apply to positive EBIT only; reinvestment is floored at zero.
C3: 2026 | D3: 2027 | E3: 2028 | F3: 2029 | G3: 2030 | H3: 2031 | I3: 2032 | J3: 2033 | K3: 2034 | L3: 2035 | M3: 2036
A4: Year index t | C4: 1 | D4: 2 | E4: 3 | F4: 4 | G4: 5 | H4: 6 | I4: 7 | J4: 8 | K4: 9 | L4: 10 | M4: 11
A5: Tax rate (ramps to marginal) | C5: =Inputs!$B$32+(Inputs!$B$33-Inputs!$B$32)*C$4/11 -> 0.11363636 | D5: =Inputs!$B$32+(Inputs!$B$33-Inputs!$B$32)*D$4/11 -> 0.12727273 | E5: =Inputs!$B$32+(Inputs!$B$33-Inputs!$B$32)*E$4/11 -> 0.14090909 | F5: =Inputs!$B$32+(Inputs!$B$33-Inputs!$B$32)*F$4/11 -> 0.15454545 | G5: =Inputs!$B$32+(Inputs!$B$33-Inputs!$B$32)*G$4/11 -> 0.16818182 | H5: =Inputs!$B$32+(Inputs!$B$33-Inputs!$B$32)*H$4/11 -> 0.18181818 | I5: =Inputs!$B$32+(Inputs!$B$33-Inputs!$B$32)*I$4/11 -> 0.19545455 | J5: =Inputs!$B$32+(Inputs!$B$33-Inputs!$B$32)*J$4/11 -> 0.20909091 | ... M5: =Inputs!$B$32+(Inputs!$B$33-Inputs!$B$32)*M$4/11 -> 0.25
A6: Discount factor 1/(1+WACC)^t | C6: =1/(1+Inputs!$B$29)^C$4 -> 0.92378753 | D6: =1/(1+Inputs!$B$29)^D$4 -> 0.8533834 | E6: =1/(1+Inputs!$B$29)^E$4 -> 0.78834494 | F6: =1/(1+Inputs!$B$29)^F$4 -> 0.72826322 | G6: =1/(1+Inputs!$B$29)^G$4 -> 0.67276048 | H6: =1/(1+Inputs!$B$29)^H$4 -> 0.62148775 | I6: =1/(1+Inputs!$B$29)^I$4 -> 0.57412263 | J6: =1/(1+Inputs!$B$29)^J$4 -> 0.53036732 | ... M6: =1/(1+Inputs!$B$29)^M$4 -> 0.4181124
A8: Launch | D8: growth to 2036 target g: | F8: =(Inputs!$B$7/Inputs!$B$6)^(1/11)-1 -> 0.23046493
A9: Revenue | C9: =(Inputs!$B$6)*(1+DCF!$F$8) -> 5027.6797 | D9: =C9*(1+DCF!$F$8) -> 6186.3835 | E9: =D9*(1+DCF!$F$8) -> 7612.1279 | F9: =E9*(1+DCF!$F$8) -> 9366.4565 | G9: =F9*(1+DCF!$F$8) -> 11525.096 | H9: =G9*(1+DCF!$F$8) -> 14181.227 | I9: =H9*(1+DCF!$F$8) -> 17449.502 | J9: =I9*(1+DCF!$F$8) -> 21471 | K9: =J9*(1+DCF!$F$8) -> 26419.313 | ... M9: =L9*(1+DCF!$F$8) -> 40000
A10: (x) Operating margin | C10: =Inputs!$B$8+(Inputs!$B$9-Inputs!$B$8)*C$4/11 -> 0.31363636 | D10: =Inputs!$B$8+(Inputs!$B$9-Inputs!$B$8)*D$4/11 -> 0.32727273 | E10: =Inputs!$B$8+(Inputs!$B$9-Inputs!$B$8)*E$4/11 -> 0.34090909 | F10: =Inputs!$B$8+(Inputs!$B$9-Inputs!$B$8)*F$4/11 -> 0.35454545 | G10: =Inputs!$B$8+(Inputs!$B$9-Inputs!$B$8)*G$4/11 -> 0.36818182 | H10: =Inputs!$B$8+(Inputs!$B$9-Inputs!$B$8)*H$4/11 -> 0.38181818 | I10: =Inputs!$B$8+(Inputs!$B$9-Inputs!$B$8)*I$4/11 -> 0.39545455 | J10: =Inputs!$B$8+(Inputs!$B$9-Inputs!$B$8)*J$4/11 -> 0.40909091 | ... M10: =Inputs!$B$8+(Inputs!$B$9-Inputs!$B$8)*M$4/11 -> 0.45
A11: (=) EBIT | C11: =C9*C10 -> 1576.8632 | D11: =D9*D10 -> 2024.6346 | E11: =E9*E10 -> 2595.0436 | F11: =F9*F10 -> 3320.8346 | G11: =G9*G10 -> 4243.3309 | H11: =H9*H10 -> 5414.6502 | I11: =I9*I10 -> 6900.4849 | J11: =J9*J10 -> 8783.591 | ... M11: =M9*M10 -> 18000
A12: (-) Taxes (on positive EBIT) | C12: =C$5*MAX(C11,0) -> 179.189 | D12: =D$5*MAX(D11,0) -> 257.68077 | E12: =E$5*MAX(E11,0) -> 365.66524 | F12: =F$5*MAX(F11,0) -> 513.21989 | G12: =G$5*MAX(G11,0) -> 713.6511 | H12: =H$5*MAX(H11,0) -> 984.48185 | I12: =I$5*MAX(I11,0) -> 1348.7311 | J12: =J$5*MAX(J11,0) -> 1836.569 | ... M12: =M$5*MAX(M11,0) -> 4500
A13: (-) Reinvestment (chg. revenue / sales-to-capital) | C13: =MAX(C9-(Inputs!$B$6),0)/Inputs!$B$10 -> 269.05134 | D13: =MAX(D9-C9,0)/Inputs!$B$10 -> 331.05824 | E13: =MAX(E9-D9,0)/Inputs!$B$10 -> 407.35555 | F13: =MAX(F9-E9,0)/Inputs!$B$10 -> 501.23672 | G13: =MAX(G9-F9,0)/Inputs!$B$10 -> 616.7542 | H13: =MAX(H9-G9,0)/Inputs!$B$10 -> 758.89441 | I13: =MAX(I9-H9,0)/Inputs!$B$10 -> 933.79296 | J13: =MAX(J9-I9,0)/Inputs!$B$10 -> 1148.9995 | K13: =MAX(K9-J9,0)/Inputs!$B$10 -> 1413.8036 | ... M13: =MAX(M9-L9,0)/Inputs!$B$10 -> 2140.5607
A14: (=) Free cash flow (FCFF) | C14: =C11-C12-C13 -> 1128.6228 | D14: =D11-D12-D13 -> 1435.8956 | E14: =E11-E12-E13 -> 1822.0228 | F14: =F11-F12-F13 -> 2306.378 | G14: =G11-G12-G13 -> 2912.9256 | H14: =H11-H12-H13 -> 3671.2739 | I14: =I11-I12-I13 -> 4617.9608 | J14: =J11-J12-J13 -> 5798.0225 | ... M14: =M11-M12-M13 -> 11359.439
A15: (x) Discount factor | C15: =C$6 -> 0.92378753 | D15: =D$6 -> 0.8533834 | E15: =E$6 -> 0.78834494 | F15: =F$6 -> 0.72826322 | G15: =G$6 -> 0.67276048 | H15: =H$6 -> 0.62148775 | I15: =I$6 -> 0.57412263 | J15: =J$6 -> 0.53036732 | ... M15: =M$6 -> 0.4181124
A16: (=) PV of FCFF | C16: =C14*C15 -> 1042.6077 | D16: =D14*D15 -> 1225.3695 | E16: =E14*E15 -> 1436.3825 | F16: =F14*F15 -> 1679.6502 | G16: =G14*G15 -> 1959.7012 | H16: =H14*H15 -> 2281.6517 | I16: =I14*I15 -> 2651.2758 | J16: =J14*J15 -> 3075.0817 | ... M16: =M14*M15 -> 4749.5224
A18: Terminal value (2037 onward)
A19: EBIT 2037 after tax = EBIT 2036 x (1+g) x (1-marginal tax) | B19: =M11*(1+Inputs!$B$30)*(1-Inputs!$B$33) -> 14115.6
A20: (-) Perpetuity reinvestment: g / ROIC of the above | B20: =B19*Inputs!$B$30/Inputs!$B$31 -> 4291.1424
A21: (=) FCFF 2037 | B21: =B19-B20 -> 9824.4576
A22: Terminal value at 2036 = FCFF 2037 / (WACC - g) | B22: =B21/(Inputs!$B$29-Inputs!$B$30) -> 266245.46
A23: PV of terminal value = TV x discount factor 2036 | B23: =B22*M15 -> 111320.53
A24: Segment operating value = sum of PV(FCFF) + PV(TV) | B24: =SUM(C16:M16)+B23 -> 139097.63 | C24: Python check: | D24: 139098
A26: Starlink | D26: growth to 2036 target g: | F26: =(Inputs!$B$14/Inputs!$B$13)^(1/11)-1 -> 0.23873745
A27: Revenue | C27: =(Inputs!$B$13)*(1+DCF!$F$26) -> 14105.503 | D27: =C27*(1+DCF!$F$26) -> 17473.015 | E27: =D27*(1+DCF!$F$26) -> 21644.478 | F27: =E27*(1+DCF!$F$26) -> 26811.826 | G27: =F27*(1+DCF!$F$26) -> 33212.812 | H27: =G27*(1+DCF!$F$26) -> 41141.954 | I27: =H27*(1+DCF!$F$26) -> 50964.079 | J27: =I27*(1+DCF!$F$26) -> 63131.113 | K27: =J27*(1+DCF!$F$26) -> 78202.874 | ... M27: =L27*(1+DCF!$F$26) -> 120000
A28: (x) Operating margin | C28: =Inputs!$B$15+(Inputs!$B$16-Inputs!$B$15)*C$4/11 -> 0.37272727 | D28: =Inputs!$B$15+(Inputs!$B$16-Inputs!$B$15)*D$4/11 -> 0.39545455 | E28: =Inputs!$B$15+(Inputs!$B$16-Inputs!$B$15)*E$4/11 -> 0.41818182 | F28: =Inputs!$B$15+(Inputs!$B$16-Inputs!$B$15)*F$4/11 -> 0.44090909 | G28: =Inputs!$B$15+(Inputs!$B$16-Inputs!$B$15)*G$4/11 -> 0.46363636 | H28: =Inputs!$B$15+(Inputs!$B$16-Inputs!$B$15)*H$4/11 -> 0.48636364 | I28: =Inputs!$B$15+(Inputs!$B$16-Inputs!$B$15)*I$4/11 -> 0.50909091 | J28: =Inputs!$B$15+(Inputs!$B$16-Inputs!$B$15)*J$4/11 -> 0.53181818 | ... M28: =Inputs!$B$15+(Inputs!$B$16-Inputs!$B$15)*M$4/11 -> 0.6
A29: (=) EBIT | C29: =C27*C28 -> 5257.5058 | D29: =D27*D28 -> 6909.7832 | E29: =E27*E28 -> 9051.3272 | F29: =F27*F28 -> 11821.578 | G29: =G27*G28 -> 15398.667 | H29: =H27*H28 -> 20009.95 | I29: =I27*I28 -> 25945.349 | J29: =J27*J28 -> 33574.274 | ... M29: =M27*M28 -> 72000
A30: (-) Taxes (on positive EBIT) | C30: =C$5*MAX(C29,0) -> 597.44384 | D30: =D$5*MAX(D29,0) -> 879.42696 | E30: =E$5*MAX(E29,0) -> 1275.4143 | F30: =F$5*MAX(F29,0) -> 1826.9711 | G30: =G$5*MAX(G29,0) -> 2589.7759 | H30: =H$5*MAX(H29,0) -> 3638.1728 | I30: =I$5*MAX(I29,0) -> 5071.1365 | J30: =J$5*MAX(J29,0) -> 7020.0755 | ... M30: =M$5*MAX(M29,0) -> 18000
A31: (-) Reinvestment (chg. revenue / sales-to-capital) | C31: =MAX(C27-(Inputs!$B$13),0)/Inputs!$B$17 -> 679.62582 | D31: =MAX(D27-C27,0)/Inputs!$B$17 -> 841.87796 | E31: =MAX(E27-D27,0)/Inputs!$B$17 -> 1042.8657 | F31: =MAX(F27-E27,0)/Inputs!$B$17 -> 1291.8369 | G31: =MAX(G27-F27,0)/Inputs!$B$17 -> 1600.2467 | H31: =MAX(H27-G27,0)/Inputs!$B$17 -> 1982.2855 | I31: =MAX(I27-H27,0)/Inputs!$B$17 -> 2455.5313 | J31: =MAX(J27-I27,0)/Inputs!$B$17 -> 3041.7585 | K31: =MAX(K27-J27,0)/Inputs!$B$17 -> 3767.9402 | ... M31: =MAX(M27-L27,0)/Inputs!$B$17 -> 5781.7929
A32: (=) Free cash flow (FCFF) | C32: =C29-C30-C31 -> 3980.4361 | D32: =D29-D30-D31 -> 5188.4783 | E32: =E29-E30-E31 -> 6733.0472 | F32: =F29-F30-F31 -> 8702.7697 | G32: =G29-G30-G31 -> 11208.645 | H32: =H29-H30-H31 -> 14389.492 | I32: =I29-I30-I31 -> 18418.682 | J32: =J29-J30-J31 -> 23512.44 | ... M32: =M29-M30-M31 -> 48218.207
A33: (x) Discount factor | C33: =C$6 -> 0.92378753 | D33: =D$6 -> 0.8533834 | E33: =E$6 -> 0.78834494 | F33: =F$6 -> 0.72826322 | G33: =G$6 -> 0.67276048 | H33: =H$6 -> 0.62148775 | I33: =I$6 -> 0.57412263 | J33: =J$6 -> 0.53036732 | ... M33: =M$6 -> 0.4181124
A34: (=) PV of FCFF | C34: =C32*C33 -> 3677.0772 | D34: =D32*D33 -> 4427.7613 | E34: =E32*E33 -> 5307.9637 | F34: =F32*F33 -> 6337.9071 | G34: =G32*G33 -> 7540.7334 | H34: =H32*H33 -> 8942.893 | I34: =I32*I33 -> 10574.582 | J34: =J32*J33 -> 12470.23 | ... M34: =M32*M33 -> 20160.63
A36: Terminal value (2037 onward)
A37: EBIT 2037 after tax = EBIT 2036 x (1+g) x (1-marginal tax) | B37: =M29*(1+Inputs!$B$30)*(1-Inputs!$B$33) -> 56462.4
A38: (-) Perpetuity reinvestment: g / ROIC of the above | B38: =B37*Inputs!$B$30/Inputs!$B$31 -> 17164.57
A39: (=) FCFF 2037 | B39: =B37-B38 -> 39297.83
A40: Terminal value at 2036 = FCFF 2037 / (WACC - g) | B40: =B39/(Inputs!$B$29-Inputs!$B$30) -> 1064981.9
A41: PV of terminal value = TV x discount factor 2036 | B41: =B40*M33 -> 445282.12
A42: Segment operating value = sum of PV(FCFF) + PV(TV) | B42: =SUM(C34:M34)+B41 -> 556606.57 | C42: Python check: | D42: 556607
A44: xAI | D44: growth to 2036 target g: | F44: =(Inputs!$B$21/Inputs!$B$20)^(1/11)-1 -> 0.42705096
A45: Revenue | C45: =(Inputs!$B$20)*(1+DCF!$F$44) -> 4567.9901 | D45: =C45*(1+DCF!$F$44) -> 6518.7547 | E45: =D45*(1+DCF!$F$44) -> 9302.5952 | F45: =E45*(1+DCF!$F$44) -> 13275.277 | G45: =F45*(1+DCF!$F$44) -> 18944.497 | H45: =G45*(1+DCF!$F$44) -> 27034.763 | I45: =H45*(1+DCF!$F$44) -> 38579.985 | J45: =I45*(1+DCF!$F$44) -> 55055.604 | K45: =J45*(1+DCF!$F$44) -> 78567.153 | ... M45: =L45*(1+DCF!$F$44) -> 160000
...

Sheet Options
A1: Real options — paper Section 5, Appendix A.2 (values $M)
A2: Expansion claims by their standalone closed form p x [M N(d1) - I N(d2)] x (1+r)^-tau, validated against the paper's simulation in Appendix A.2. Mars as the exact probability tree. The abandonment option is imported from the Python least-squares Monte Carlo.
A4: Starlink direct-to-cell (exercise-at-gate)
A5: Underlying M | B5: =DCF!$B$78 -> 56737.281
A6: d1 = [ln(M/I) + sigma^2/2] / sigma | B6: =(LN(B5/Inputs!$B$47)+0.5*Inputs!$B$49^2)/Inputs!$B$49 -> 3.0995907
A7: d2 = d1 - sigma | B7: =B6-Inputs!$B$49 -> 2.5495907
A8: Option value | B8: =1*(B5*_xlfn.NORM.S.DIST(B6,TRUE)-Inputs!$B$47*_xlfn.NORM.S.DIST(B7,TRUE))/(1+Inputs!$B$29)^Inputs!$B$48 -> 32587.606 | C8: 32588 | D8: Python checks: closed form 32,588; the paper's simulated value 32,614 (same paths as the firm model; gap = Monte-Carlo error)
A10: Starship heavy lift (gated on the technical trigger)
A11: Underlying M | B11: =Inputs!$B$50 -> 110000
A12: d1 = [ln(M/I) + sigma^2/2] / sigma | B12: =(LN(B11/Inputs!$B$51)+0.5*Inputs!$B$53^2)/Inputs!$B$53 -> 2.848566
A13: d2 = d1 - sigma | B13: =B12-Inputs!$B$53 -> 2.348566
A14: Option value | B14: =Inputs!$B$54*(B11*_xlfn.NORM.S.DIST(B12,TRUE)-Inputs!$B$51*_xlfn.NORM.S.DIST(B13,TRUE))/(1+Inputs!$B$29)^Inputs!$B$52 -> 32309.112 | C14: 32309 | D14: Python checks: closed form 32,309; the paper's simulated value 32,304 (same paths as the firm model; gap = Monte-Carlo error)
A16: Mars sovereign-program claim (exact probability tree)
A17: State (highest realized) | B17: Value ($M) | C17: Probability
A18: Settlement | B18: =MAX(Inputs!$B$64*Inputs!$B$57*(1-Inputs!$B$33)/Inputs!$B$29-Inputs!$B$65,0) -> 12272.727 | C18: =Inputs!$B$54*Inputs!$B$63*Inputs!$B$66 -> 0.0375
A19: Crewed, not settlement | B19: =MAX(Inputs!$B$61*Inputs!$B$57*(1-Inputs!$B$33)/Inputs!$B$29-Inputs!$B$62,0) -> 1818.1818 | C19: =Inputs!$B$54*Inputs!$B$63*(1-Inputs!$B$66) -> 0.1125
A20: Robotic only | B20: =MAX(Inputs!$B$59*Inputs!$B$57*(1-Inputs!$B$33)/Inputs!$B$29-0,0) -> 1363.6364 | C20: =Inputs!$B$60*(1-Inputs!$B$54*Inputs!$B$63) -> 0.765
A21: Mars claim, discounted from the start year | B21: =SUMPRODUCT(B18:B20,C18:C20)/(1+Inputs!$B$29)^Inputs!$B$58 -> 773.03162 | C21: 772 | D21: Python check (simulated tree). Value per state = max(revenue x margin x (1-tax) / WACC - co-investment, 0), a flat perpetuity.
A23: xAI abandonment option (imported)
A24: Value at zero salvage | B24: =Inputs!$B$69 -> 1492 | D24: From the Python least-squares Monte Carlo (paper Sec. 5.2); optimal stopping has no formula representation — see venture_option.py
A26: Totals
A27: Expansion claims + Mars | B27: =Options!$B$8+Options!$B$14+Options!$B$21 -> 65669.75
A28: All options incl. abandonment | B28: =B27+Inputs!$B$69 -> 67161.75
A29: Equity + all options ($M) | B29: =DCF!$B$87+B28 -> 1070732
A30: Per share ($) | B30: =B29/Inputs!$B$37 -> 81.791461

Sheet MonteCarlo
A1: Monte Carlo — the distribution of equity value (1,000 trials; paper Sec. 4.3)
A2: Each row is one trial of the correlated three-segment model of Appendix A.1: a common demand factor per year (correlation rho), declining revenue volatility, the same cash-flow construction as the DCF tab. Press F9 to redraw. Excel's RAND() is not seeded, so figures move by Monte-Carlo error around the Python values; the paper's numbers use 200,000 fixed-seed paths.
C3: 2026 | D3: 2027 | E3: 2028 | F3: 2029 | G3: 2030 | H3: 2031 | I3: 2032 | J3: 2033 | K3: 2034 | L3: 2035 | M3: 2036
A4: Year index t | C4: 1 | D4: 2 | E4: 3 | F4: 4 | G4: 5 | H4: 6 | I4: 7 | J4: 8 | K4: 9 | L4: 10 | M4: 11 | P4: Summary of the simulated distribution | U4: Histogram ($T bins, count of trials)
A5: Launch: sigma_t | C5: =Inputs!$B$11*EXP(-Inputs!$B$39*C$4)+Inputs!$B$12*(1-EXP(-Inputs!$B$39*C$4)) -> 0.16187308 | D5: =Inputs!$B$11*EXP(-Inputs!$B$39*D$4)+Inputs!$B$12*(1-EXP(-Inputs!$B$39*D$4)) -> 0.147032 | E5: =Inputs!$B$11*EXP(-Inputs!$B$39*E$4)+Inputs!$B$12*(1-EXP(-Inputs!$B$39*E$4)) -> 0.13488116 | F5: =Inputs!$B$11*EXP(-Inputs!$B$39*F$4)+Inputs!$B$12*(1-EXP(-Inputs!$B$39*F$4)) -> 0.1249329 | G5: =Inputs!$B$11*EXP(-Inputs!$B$39*G$4)+Inputs!$B$12*(1-EXP(-Inputs!$B$39*G$4)) -> 0.11678794 | H5: =Inputs!$B$11*EXP(-Inputs!$B$39*H$4)+Inputs!$B$12*(1-EXP(-Inputs!$B$39*H$4)) -> 0.11011942 | I5: =Inputs!$B$11*EXP(-Inputs!$B$39*I$4)+Inputs!$B$12*(1-EXP(-Inputs!$B$39*I$4)) -> 0.1046597 | J5: =Inputs!$B$11*EXP(-Inputs!$B$39*J$4)+Inputs!$B$12*(1-EXP(-Inputs!$B$39*J$4)) -> 0.10018965 | ... M5: =Inputs!$B$11*EXP(-Inputs!$B$39*M$4)+Inputs!$B$12*(1-EXP(-Inputs!$B$39*M$4)) -> 0.091080316 | P5: Mean equity ($M) | R5: =AVERAGE(DM14:DM1013) -> 997221.72 | S5: Python (200k paths): 1,002,249 | U5: 0.2 | V5: 0.4 | W5: 0.6 | X5: 0.8 | Y5: 1 | Z5: 1.2 | AA5: 1.4 | AB5: 1.6 | AC5: 1.8 | AD5: 2 | AE5: 2.2 | AF5: 2.4 | AG5: 2.6 | AH5: 2.8 | AI5: 3
A6: Starlink: sigma_t | C6: =Inputs!$B$18*EXP(-Inputs!$B$39*C$4)+Inputs!$B$19*(1-EXP(-Inputs!$B$39*C$4)) -> 0.19824769 | D6: =Inputs!$B$18*EXP(-Inputs!$B$39*D$4)+Inputs!$B$19*(1-EXP(-Inputs!$B$39*D$4)) -> 0.18043841 | E6: =Inputs!$B$18*EXP(-Inputs!$B$39*E$4)+Inputs!$B$19*(1-EXP(-Inputs!$B$39*E$4)) -> 0.1658574 | F6: =Inputs!$B$18*EXP(-Inputs!$B$39*F$4)+Inputs!$B$19*(1-EXP(-Inputs!$B$39*F$4)) -> 0.15391948 | G6: =Inputs!$B$18*EXP(-Inputs!$B$39*G$4)+Inputs!$B$19*(1-EXP(-Inputs!$B$39*G$4)) -> 0.14414553 | H6: =Inputs!$B$18*EXP(-Inputs!$B$39*H$4)+Inputs!$B$19*(1-EXP(-Inputs!$B$39*H$4)) -> 0.13614331 | I6: =Inputs!$B$18*EXP(-Inputs!$B$39*I$4)+Inputs!$B$19*(1-EXP(-Inputs!$B$39*I$4)) -> 0.12959164 | J6: =Inputs!$B$18*EXP(-Inputs!$B$39*J$4)+Inputs!$B$19*(1-EXP(-Inputs!$B$39*J$4)) -> 0.12422758 | ... M6: =Inputs!$B$18*EXP(-Inputs!$B$39*M$4)+Inputs!$B$19*(1-EXP(-Inputs!$B$39*M$4)) -> 0.11329638 | P6: Std deviation | R6: =_xlfn.STDEV.S(DM14:DM1013) -> 423862.7 | U6: =COUNTIFS(DM14:DM1013,">=200000",DM14:DM1013,"<400000") -> 8 | V6: =COUNTIFS(DM14:DM1013,">=400000",DM14:DM1013,"<600000") -> 107 | W6: =COUNTIFS(DM14:DM1013,">=600000",DM14:DM1013,"<800000") -> 261 | X6: =COUNTIFS(DM14:DM1013,">=800000",DM14:DM1013,"<1000000") -> 224 | Y6: =COUNTIFS(DM14:DM1013,">=1000000",DM14:DM1013,"<1200000") -> 163 | Z6: =COUNTIFS(DM14:DM1013,">=1200000",DM14:DM1013,"<1400000") -> 102 | AA6: =COUNTIFS(DM14:DM1013,">=1400000",DM14:DM1013,"<1600000") -> 56 | AB6: =COUNTIFS(DM14:DM1013,">=1600000",DM14:DM1013,"<1800000") -> 32 | AC6: =COUNTIFS(DM14:DM1013,">=1800000",DM14:DM1013,"<2000000") -> 19 | AD6: =COUNTIFS(DM14:DM1013,">=2000000",DM14:DM1013,"<2200000") -> 10 | AE6: =COUNTIFS(DM14:DM1013,">=2200000",DM14:DM1013,"<2400000") -> 5 | AF6: =COUNTIFS(DM14:DM1013,">=2400000",DM14:DM1013,"<2600000") -> 3 | AG6: =COUNTIFS(DM14:DM1013,">=2600000",DM14:DM1013,"<2800000") -> 4 | AH6: =COUNTIFS(DM14:DM1013,">=2800000",DM14:DM1013,"<3000000") -> 3 | AI6: =COUNTIFS(DM14:DM1013,">=3000000",DM14:DM1013,"<3200000") -> 1
A7: xAI: sigma_t | C7: =Inputs!$B$25*EXP(-Inputs!$B$39*C$4)+Inputs!$B$26*(1-EXP(-Inputs!$B$39*C$4)) -> 0.35468269 | D7: =Inputs!$B$25*EXP(-Inputs!$B$39*D$4)+Inputs!$B$26*(1-EXP(-Inputs!$B$39*D$4)) -> 0.31758001 | E7: =Inputs!$B$25*EXP(-Inputs!$B$39*E$4)+Inputs!$B$26*(1-EXP(-Inputs!$B$39*E$4)) -> 0.28720291 | F7: =Inputs!$B$25*EXP(-Inputs!$B$39*F$4)+Inputs!$B$26*(1-EXP(-Inputs!$B$39*F$4)) -> 0.26233224 | G7: =Inputs!$B$25*EXP(-Inputs!$B$39*G$4)+Inputs!$B$26*(1-EXP(-Inputs!$B$39*G$4)) -> 0.24196986 | H7: =Inputs!$B$25*EXP(-Inputs!$B$39*H$4)+Inputs!$B$26*(1-EXP(-Inputs!$B$39*H$4)) -> 0.22529855 | I7: =Inputs!$B$25*EXP(-Inputs!$B$39*I$4)+Inputs!$B$26*(1-EXP(-Inputs!$B$39*I$4)) -> 0.21164924 | J7: =Inputs!$B$25*EXP(-Inputs!$B$39*J$4)+Inputs!$B$26*(1-EXP(-Inputs!$B$39*J$4)) -> 0.20047413 | ... M7: =Inputs!$B$25*EXP(-Inputs!$B$39*M$4)+Inputs!$B$26*(1-EXP(-Inputs!$B$39*M$4)) -> 0.17770079 | P7: MC std error of mean | R7: =_xlfn.STDEV.S(DM14:DM1013)/SQRT(1000) -> 13403.716
A8: Launch: drift ln(1+g) | B8: =LN(1+DCF!$F$8) -> 0.20739209 | P8: 5th percentile | R8: =_xlfn.PERCENTILE.INC(DM14:DM1013,0.05) -> 521926.18 | S8: Python: 514,826
A9: Starlink: drift ln(1+g) | B9: =LN(1+DCF!$F$26) -> 0.21409267 | P9: Median | R9: =_xlfn.PERCENTILE.INC(DM14:DM1013,0.5) -> 908876.59 | S9: Python: 915,244
A10: xAI: drift ln(1+g) | B10: =LN(1+DCF!$F$44) -> 0.35561005 | P10: 95th percentile | R10: =_xlfn.PERCENTILE.INC(DM14:DM1013,0.95) -> 1760783.6 | S10: Python: 1,777,523
P11: P(equity > $1.8T) | R11: =COUNTIF(DM14:DM1013,">1800000")/1000 -> 0.047 | S11: Python: 5%
A13: Trial | C13: f 2026 | D13: f 2027 | E13: f 2028 | F13: f 2029 | G13: f 2030 | H13: f 2031 | I13: f 2032 | J13: f 2033 | K13: f 2034 | L13: f 2035 | M13: f 2036 | N13: z La 26 | O13: z La 27 | P13: z La 28 | Q13: z La 29 | R13: z La 30 | S13: z La 31 | T13: z La 32 | U13: z La 33 | V13: z La 34 | W13: z La 35 | X13: z La 36 | Y13: z St 26 | Z13: z St 27 | AA13: z St 28 | AB13: z St 29 | AC13: z St 30 | AD13: z St 31 | AE13: z St 32 | AF13: z St 33 | AG13: z St 34 | AH13: z St 35 | AI13: z St 36 | AJ13: z xA 26 | AK13: z xA 27 | AL13: z xA 28 | AM13: z xA 29 | AN13: z xA 30 | AO13: z xA 31 | AP13: z xA 32 | AQ13: z xA 33 | AR13: z xA 34 | AS13: z xA 35 | AT13: z xA 36 | AU13: R La 26 | AV13: R La 27 | AW13: R La 28 | AX13: R La 29 | AY13: R La 30 | AZ13: R La 31 | BA13: R La 32 | BB13: R La 33 | BC13: R La 34 | BD13: R La 35 | BE13: R La 36 | BF13: R St 26 | BG13: R St 27 | BH13: R St 28 | BI13: R St 29 | BJ13: R St 30 | BK13: R St 31 | BL13: R St 32 | BM13: R St 33 | BN13: R St 34 | BO13: R St 35 | BP13: R St 36 | BQ13: R xA 26 | BR13: R xA 27 | BS13: R xA 28 | BT13: R xA 29 | BU13: R xA 30 | BV13: R xA 31 | BW13: R xA 32 | BX13: R xA 33 | BY13: R xA 34 | BZ13: R xA 35 | CA13: R xA 36 | CB13: PV La 26 | CC13: PV La 27 | CD13: PV La 28 | CE13: PV La 29 | CF13: PV La 30 | CG13: PV La 31 | CH13: PV La 32 | CI13: PV La 33 | CJ13: PV La 34 | CK13: PV La 35 | CL13: PV La 36 | CM13: PV St 26 | CN13: PV St 27 | CO13: PV St 28 | CP13: PV St 29 | CQ13: PV St 30 | CR13: PV St 31 | CS13: PV St 32 | CT13: PV St 33 | CU13: PV St 34 | CV13: PV St 35 | CW13: PV St 36 | CX13: PV xA 26 | CY13: PV xA 27 | CZ13: PV xA 28 | DA13: PV xA 29 | DB13: PV xA 30 | DC13: PV xA 31 | DD13: PV xA 32 | DE13: PV xA 33 | DF13: PV xA 34 | DG13: PV xA 35 | DH13: PV xA 36 | DI13: Launch value | DJ13: Starlink value | DK13: xAI value | DM13: Equity ($M)
A14: 1 | C14: =_xlfn.NORM.S.INV(RAND()) -> -0.30016433 | D14: =_xlfn.NORM.S.INV(RAND()) -> -1.6884345 | E14: =_xlfn.NORM.S.INV(RAND()) -> -0.68516792 | F14: =_xlfn.NORM.S.INV(RAND()) -> 1.6121494 | G14: =_xlfn.NORM.S.INV(RAND()) -> -0.76011499 | H14: =_xlfn.NORM.S.INV(RAND()) -> -0.51186066 | I14: =_xlfn.NORM.S.INV(RAND()) -> 0.70463139 | J14: =_xlfn.NORM.S.INV(RAND()) -> 0.10479499 | ... M14: =_xlfn.NORM.S.INV(RAND()) -> -1.6454338 | N14: =SQRT(Inputs!$B$38)*C14+SQRT(1-Inputs!$B$38)*_xlfn.NORM.S.INV(RAND()) -> -0.77212621 | O14: =SQRT(Inputs!$B$38)*D14+SQRT(1-Inputs!$B$38)*_xlfn.NORM.S.INV(RAND()) -> -0.56081031 | P14: =SQRT(Inputs!$B$38)*E14+SQRT(1-Inputs!$B$38)*_xlfn.NORM.S.INV(RAND()) -> 0.30254546 | Q14: =SQRT(Inputs!$B$38)*F14+SQRT(1-Inputs!$B$38)*_xlfn.NORM.S.INV(RAND()) -> 1.5800858 | R14: =SQRT(Inputs!$B$38)*G14+SQRT(1-Inputs!$B$38)*_xlfn.NORM.S.INV(RAND()) -> -0.25832461 | S14: =SQRT(Inputs!$B$38)*H14+SQRT(1-Inputs!$B$38)*_xlfn.NORM.S.INV(RAND()) -> -0.9464498 | T14: =SQRT(Inputs!$B$38)*I14+SQRT(1-Inputs!$B$38)*_xlfn.NORM.S.INV(RAND()) -> -0.014798184 | U14: =SQRT(Inputs!$B$38)*J14+SQRT(1-Inputs!$B$38)*_xlfn.NORM.S.INV(RAND()) -> 1.5267627 | ... X14: =SQRT(Inputs!$B$38)*M14+SQRT(1-Inputs!$B$38)*_xlfn.NORM.S.INV(RAND()) -> -1.1486193 | Y14: =SQRT(Inputs!$B$38)*C14+SQRT(1-Inputs!$B$38)*_xlfn.NORM.S.INV(RAND()) -> -0.26813794 | Z14: =SQRT(Inputs!$B$38)*D14+SQRT(1-Inputs!$B$38)*_xlfn.NORM.S.INV(RAND()) -> -0.37460193 | AA14: =SQRT(Inputs!$B$38)*E14+SQRT(1-Inputs!$B$38)*_xlfn.NORM.S.INV(RAND()) -> -0.84949988 | AB14: =SQRT(Inputs!$B$38)*F14+SQRT(1-Inputs!$B$38)*_xlfn.NORM.S.INV(RAND()) -> 0.053225127 | AC14: =SQRT(Inputs!$B$38)*G14+SQRT(1-Inputs!$B$38)*_xlfn.NORM.S.INV(RAND()) -> -1.4756267 | AD14: =SQRT(Inputs!$B$38)*H14+SQRT(1-Inputs!$B$38)*_xlfn.NORM.S.INV(RAND()) -> -1.1502349 | AE14: =SQRT(Inputs!$B$38)*I14+SQRT(1-Inputs!$B$38)*_xlfn.NORM.S.INV(RAND()) -> 0.9085652 | AF14: =SQRT(Inputs!$B$38)*J14+SQRT(1-Inputs!$B$38)*_xlfn.NORM.S.INV(RAND()) -> 0.56956074 | ... AI14: =SQRT(Inputs!$B$38)*M14+SQRT(1-Inputs!$B$38)*_xlfn.NORM.S.INV(RAND()) -> -1.3236524 | AJ14: =SQRT(Inputs!$B$38)*C14+SQRT(1-Inputs!$B$38)*_xlfn.NORM.S.INV(RAND()) -> 1.549427 | AK14: =SQRT(Inputs!$B$38)*D14+SQRT(1-Inputs!$B$38)*_xlfn.NORM.S.INV(RAND()) -> -1.8177563 | AL14: =SQRT(Inputs!$B$38)*E14+SQRT(1-Inputs!$B$38)*_xlfn.NORM.S.INV(RAND()) -> -0.38373319 | AM14: =SQRT(Inputs!$B$38)*F14+SQRT(1-Inputs!$B$38)*_xlfn.NORM.S.INV(RAND()) -> 0.75392933 | AN14: =SQRT(Inputs!$B$38)*G14+SQRT(1-Inputs!$B$38)*_xlfn.NORM.S.INV(RAND()) -> -0.28380304 | AO14: =SQRT(Inputs!$B$38)*H14+SQRT(1-Inputs!$B$38)*_xlfn.NORM.S.INV(RAND()) -> 0.64374081 | AP14: =SQRT(Inputs!$B$38)*I14+SQRT(1-Inputs!$B$38)*_xlfn.NORM.S.INV(RAND()) -> -0.16864156 | AQ14: =SQRT(Inputs!$B$38)*J14+SQRT(1-Inputs!$B$38)*_xlfn.NORM.S.INV(RAND()) -> -0.72434153 | ... AT14: =SQRT(Inputs!$B$38)*M14+SQRT(1-Inputs!$B$38)*_xlfn.NORM.S.INV(RAND()) -> -1.4851565 | AU14: =Inputs!$B$6*EXP($B$8-0.5*C$5^2+C$5*N14) -> 4379.2203 | AV14: =AU14*EXP($B$8-0.5*D$5^2+D$5*O14) -> 4908.638 | AW14: =AV14*EXP($B$8-0.5*E$5^2+E$5*P14) -> 6234.5089 | AX14: =AW14*EXP($B$8-0.5*F$5^2+F$5*Q14) -> 9272.8659 | AY14: =AX14*EXP($B$8-0.5*G$5^2+G$5*R14) -> 10995.605 | AZ14: =AY14*EXP($B$8-0.5*H$5^2+H$5*S14) -> 12116.911 | BA14: =AZ14*EXP($B$8-0.5*I$5^2+I$5*T14) -> 14805.054 | BB14: =BA14*EXP($B$8-0.5*J$5^2+J$5*U14) -> 21121.839 | BC14: =BB14*EXP($B$8-0.5*K$5^2+K$5*V14) -> 24051.511 | ... BE14: =BD14*EXP($B$8-0.5*M$5^2+M$5*X14) -> 32696.475 | BF14: =Inputs!$B$13*EXP($B$9-0.5*C$6^2+C$6*Y14) -> 13114.995 | BG14: =BF14*EXP($B$9-0.5*D$6^2+D$6*Z14) -> 14939.031 | BH14: =BG14*EXP($B$9-0.5*E$6^2+E$6*AA14) -> 15853.968 | BI14: =BH14*EXP($B$9-0.5*F$6^2+F$6*AB14) -> 19567.289 | BJ14: =BI14*EXP($B$9-0.5*G$6^2+G$6*AC14) -> 19391.949 | BK14: =BJ14*EXP($B$9-0.5*H$6^2+H$6*AD14) -> 20350.111 | BL14: =BK14*EXP($B$9-0.5*I$6^2+I$6*AE14) -> 28121.221 | BM14: =BL14*EXP($B$9-0.5*J$6^2+J$6*AF14) -> 37101.45 | BN14: =BM14*EXP($B$9-0.5*K$6^2+K$6*AG14) -> 36764.706 | ... BP14: =BO14*EXP($B$9-0.5*M$6^2+M$6*AI14) -> 40931.39 | BQ14: =Inputs!$B$20*EXP($B$10-0.5*C$7^2+C$7*AJ14) -> 7431.5046 | BR14: =BQ14*EXP($B$10-0.5*D$7^2+D$7*AK14) -> 5661.1485 | BS14: =BR14*EXP($B$10-0.5*E$7^2+E$7*AL14) -> 6943.353 | BT14: =BS14*EXP($B$10-0.5*F$7^2+F$7*AM14) -> 11667.016 | BU14: =BT14*EXP($B$10-0.5*G$7^2+G$7*AN14) -> 15095.992 | BV14: =BU14*EXP($B$10-0.5*H$7^2+H$7*AO14) -> 24280.984 | BW14: =BV14*EXP($B$10-0.5*I$7^2+I$7*AP14) -> 32694.7 | BX14: =BW14*EXP($B$10-0.5*J$7^2+J$7*AQ14) -> 39548.048 | BY14: =BX14*EXP($B$10-0.5*K$7^2+K$7*AR14) -> 51202.376 | ... CA14: =BZ14*EXP($B$10-0.5*M$7^2+M$7*AT14) -> 61944.983 | CB14: =(AU14*DCF!C$10-DCF!C$5*MAX(AU14*DCF!C$10,0)-MAX(AU14-Inputs!$B$6,0)/Inputs!$B$10)*DCF!C$6 -> 1047.2313 | CC14: =(AV14*DCF!D$10-DCF!D$5*MAX(AV14*DCF!D$10,0)-MAX(AV14-AU14,0)/Inputs!$B$10)*DCF!D$6 -> 1067.3626 | CD14: =(AW14*DCF!E$10-DCF!E$5*MAX(AW14*DCF!E$10,0)-MAX(AW14-AV14,0)/Inputs!$B$10)*DCF!E$6 -> 1140.8078 | CE14: =(AX14*DCF!F$10-DCF!F$5*MAX(AX14*DCF!F$10,0)-MAX(AX14-AW14,0)/Inputs!$B$10)*DCF!F$6 -> 1392.0451 | CF14: =(AY14*DCF!G$10-DCF!G$5*MAX(AY14*DCF!G$10,0)-MAX(AY14-AX14,0)/Inputs!$B$10)*DCF!G$6 -> 1934.3926 | CG14: =(AZ14*DCF!H$10-DCF!H$5*MAX(AZ14*DCF!H$10,0)-MAX(AZ14-AY14,0)/Inputs!$B$10)*DCF!H$6 -> 2153.399 | CH14: =(BA14*DCF!I$10-DCF!I$5*MAX(BA14*DCF!I$10,0)-MAX(BA14-AZ14,0)/Inputs!$B$10)*DCF!I$6 -> 2263.3937 | CI14: =(BB14*DCF!J$10-DCF!J$5*MAX(BB14*DCF!J$10,0)-MAX(BB14-BA14,0)/Inputs!$B$10)*DCF!J$6 -> 2667.3519 | CJ14: =(BC14*DCF!K$10-DCF!K$5*MAX(BC14*DCF!K$10,0)-MAX(BC14-BB14,0)/Inputs!$B$10)*DCF!K$6 -> 3461.7975 | ... CL14: =(BE14*DCF!M$10-DCF!M$5*MAX(BE14*DCF!M$10,0)-MAX(BE14-BD14,0)/Inputs!$B$10)*DCF!M$6 -> 4247.0494 | CM14: =(BF14*DCF!C$28-DCF!C$5*MAX(BF14*DCF!C$28,0)-MAX(BF14-Inputs!$B$13,0)/Inputs!$B$17)*DCF!C$6 -> 3603.5354 | CN14: =(BG14*DCF!D$28-DCF!D$5*MAX(BG14*DCF!D$28,0)-MAX(BG14-BF14,0)/Inputs!$B$17)*DCF!D$6 -> 4010.7386 | CO14: =(BH14*DCF!E$28-DCF!E$5*MAX(BH14*DCF!E$28,0)-MAX(BH14-BG14,0)/Inputs!$B$17)*DCF!E$6 -> 4309.8045 | CP14: =(BI14*DCF!F$28-DCF!F$5*MAX(BI14*DCF!F$28,0)-MAX(BI14-BH14,0)/Inputs!$B$17)*DCF!F$6 -> 4635.9348 | CQ14: =(BJ14*DCF!G$28-DCF!G$5*MAX(BJ14*DCF!G$28,0)-MAX(BJ14-BI14,0)/Inputs!$B$17)*DCF!G$6 -> 5031.3882 | CR14: =(BK14*DCF!H$28-DCF!H$5*MAX(BK14*DCF!H$28,0)-MAX(BK14-BJ14,0)/Inputs!$B$17)*DCF!H$6 -> 4883.9354 | CS14: =(BL14*DCF!I$28-DCF!I$5*MAX(BL14*DCF!I$28,0)-MAX(BL14-BK14,0)/Inputs!$B$17)*DCF!I$6 -> 5497.3979 | CT14: =(BM14*DCF!J$28-DCF!J$5*MAX(BM14*DCF!J$28,0)-MAX(BM14-BL14,0)/Inputs!$B$17)*DCF!J$6 -> 7085.9984 | CU14: =(BN14*DCF!K$28-DCF!K$5*MAX(BN14*DCF!K$28,0)-MAX(BN14-BM14,0)/Inputs!$B$17)*DCF!K$6 -> 7764.0894 | ... CW14: =(BP14*DCF!M$28-DCF!M$5*MAX(BP14*DCF!M$28,0)-MAX(BP14-BO14,0)/Inputs!$B$17)*DCF!M$6 -> 7461.3447 | CX14: =(BQ14*DCF!C$46-DCF!C$5*MAX(BQ14*DCF!C$46,0)-MAX(BQ14-Inputs!$B$20,0)/Inputs!$B$24)*DCF!C$6 -> -3670.3265 | CY14: =(BR14*DCF!D$46-DCF!D$5*MAX(BR14*DCF!D$46,0)-MAX(BR14-BQ14,0)/Inputs!$B$24)*DCF!D$6 -> -966.22603 | CZ14: =(BS14*DCF!E$46-DCF!E$5*MAX(BS14*DCF!E$46,0)-MAX(BS14-BR14,0)/Inputs!$B$24)*DCF!E$6 -> -1326.4733 | DA14: =(BT14*DCF!F$46-DCF!F$5*MAX(BT14*DCF!F$46,0)-MAX(BT14-BS14,0)/Inputs!$B$24)*DCF!F$6 -> -2569.7009 | DB14: =(BU14*DCF!G$46-DCF!G$5*MAX(BU14*DCF!G$46,0)-MAX(BU14-BT14,0)/Inputs!$B$24)*DCF!G$6 -> -1661.2391 | DC14: =(BV14*DCF!H$46-DCF!H$5*MAX(BV14*DCF!H$46,0)-MAX(BV14-BU14,0)/Inputs!$B$24)*DCF!H$6 -> -2854.1799 | DD14: =(BW14*DCF!I$46-DCF!I$5*MAX(BW14*DCF!I$46,0)-MAX(BW14-BV14,0)/Inputs!$B$24)*DCF!I$6 -> -1660.1556 | DE14: =(BX14*DCF!J$46-DCF!J$5*MAX(BX14*DCF!J$46,0)-MAX(BX14-BW14,0)/Inputs!$B$24)*DCF!J$6 -> -158.46489 | DF14: =(BY14*DCF!K$46-DCF!K$5*MAX(BY14*DCF!K$46,0)-MAX(BY14-BX14,0)/Inputs!$B$24)*DCF!K$6 -> 69.850648 | ... DH14: =(CA14*DCF!M$46-DCF!M$5*MAX(CA14*DCF!M$46,0)-MAX(CA14-BZ14,0)/Inputs!$B$24)*DCF!M$6 -> 3909.6216 | DI14: =SUM(CB14:CL14)+BE14*DCF!M$10*(1+Inputs!$B$30)*(1-Inputs!$B$33)*(1-Inputs!$B$30/Inputs!$B$31)/(Inputs!$B$29-Inputs!$B$30)*DCF!M$6 -> 116116.84 | DJ14: =SUM(CM14:CW14)+BP14*DCF!M$28*(1+Inputs!$B$30)*(1-Inputs!$B$33)*(1-Inputs!$B$30/Inputs!$B$31)/(Inputs!$B$29-Inputs!$B$30)*DCF!M$6 -> 213664.6 | DK14: =SUM(CX14:DH14)+CA14*DCF!M$46*(1+Inputs!$B$30)*(1-Inputs!$B$33)*(1-Inputs!$B$30/Inputs!$B$31)/(Inputs!$B$29-Inputs!$B$30)*DCF!M$6 -> 87449.584 | DM14: =DI14+DJ14+DK14+Inputs!$B$34+Inputs!$B$36-Inputs!$B$35 -> 494082.02
A15: 2 | C15: =_xlfn.NORM.S.INV(RAND()) -> 0.92353003 | D15: =_xlfn.NORM.S.INV(RAND()) -> 0.025953389 | E15: =_xlfn.NORM.S.INV(RAND()) -> -1.0652339 | F15: =_xlfn.NORM.S.INV(RAND()) -> -0.085847371 | G15: =_xlfn.NORM.S.INV(RAND()) -> -0.74126636 | H15: =_xlfn.NORM.S.INV(RAND()) -> -1.127027 | I15: =_xlfn.NORM.S.INV(RAND()) -> 0.40682181 | J15: =_xlfn.NORM.S.INV(RAND()) -> 1.1731958 | ... M15: =_xlfn.NORM.S.INV(RAND()) -> -0.094738983 | N15: =SQRT(Inputs!$B$38)*C15+SQRT(1-Inputs!$B$38)*_xlfn.NORM.S.INV(RAND()) -> 1.3135844 | O15: =SQRT(Inputs!$B$38)*D15+SQRT(1-Inputs!$B$38)*_xlfn.NORM.S.INV(RAND()) -> 0.076743268 | P15: =SQRT(Inputs!$B$38)*E15+SQRT(1-Inputs!$B$38)*_xlfn.NORM.S.INV(RAND()) -> -0.51846884 | Q15: =SQRT(Inputs!$B$38)*F15+SQRT(1-Inputs!$B$38)*_xlfn.NORM.S.INV(RAND()) -> 0.252472 | R15: =SQRT(Inputs!$B$38)*G15+SQRT(1-Inputs!$B$38)*_xlfn.NORM.S.INV(RAND()) -> -1.3351437 | S15: =SQRT(Inputs!$B$38)*H15+SQRT(1-Inputs!$B$38)*_xlfn.NORM.S.INV(RAND()) -> -1.7550109 | T15: =SQRT(Inputs!$B$38)*I15+SQRT(1-Inputs!$B$38)*_xlfn.NORM.S.INV(RAND()) -> 0.95404625 | U15: =SQRT(Inputs!$B$38)*J15+SQRT(1-Inputs!$B$38)*_xlfn.NORM.S.INV(RAND()) -> 0.070283655 | ... X15: =SQRT(Inputs!$B$38)*M15+SQRT(1-Inputs!$B$38)*_xlfn.NORM.S.INV(RAND()) -> 0.61546497 | Y15: =SQRT(Inputs!$B$38)*C15+SQRT(1-Inputs!$B$38)*_xlfn.NORM.S.INV(RAND()) -> 1.0145725 | Z15: =SQRT(Inputs!$B$38)*D15+SQRT(1-Inputs!$B$38)*_xlfn.NORM.S.INV(RAND()) -> -1.327462 | AA15: =SQRT(Inputs!$B$38)*E15+SQRT(1-Inputs!$B$38)*_xlfn.NORM.S.INV(RAND()) -> 0.99905022 | AB15: =SQRT(Inputs!$B$38)*F15+SQRT(1-Inputs!$B$38)*_xlfn.NORM.S.INV(RAND()) -> 1.6794097 | AC15: =SQRT(Inputs!$B$38)*G15+SQRT(1-Inputs!$B$38)*_xlfn.NORM.S.INV(RAND()) -> -0.62918751 | AD15: =SQRT(Inputs!$B$38)*H15+SQRT(1-Inputs!$B$38)*_xlfn.NORM.S.INV(RAND()) -> -1.335839 | AE15: =SQRT(Inputs!$B$38)*I15+SQRT(1-Inputs!$B$38)*_xlfn.NORM.S.INV(RAND()) -> 0.65527107 | AF15: =SQRT(Inputs!$B$38)*J15+SQRT(1-Inputs!$B$38)*_xlfn.NORM.S.INV(RAND()) -> 0.55632197 | ... AI15: =SQRT(Inputs!$B$38)*M15+SQRT(1-Inputs!$B$38)*_xlfn.NORM.S.INV(RAND()) -> 0.47669226 | AJ15: =SQRT(Inputs!$B$38)*C15+SQRT(1-Inputs!$B$38)*_xlfn.NORM.S.INV(RAND()) -> 0.31887492 | AK15: =SQRT(Inputs!$B$38)*D15+SQRT(1-Inputs!$B$38)*_xlfn.NORM.S.INV(RAND()) -> -0.36676824 | AL15: =SQRT(Inputs!$B$38)*E15+SQRT(1-Inputs!$B$38)*_xlfn.NORM.S.INV(RAND()) -> -0.82448535 | AM15: =SQRT(Inputs!$B$38)*F15+SQRT(1-Inputs!$B$38)*_xlfn.NORM.S.INV(RAND()) -> -1.2358924 | AN15: =SQRT(Inputs!$B$38)*G15+SQRT(1-Inputs!$B$38)*_xlfn.NORM.S.INV(RAND()) -> 1.1074882 | AO15: =SQRT(Inputs!$B$38)*H15+SQRT(1-Inputs!$B$38)*_xlfn.NORM.S.INV(RAND()) -> -2.0293819 | AP15: =SQRT(Inputs!$B$38)*I15+SQRT(1-Inputs!$B$38)*_xlfn.NORM.S.INV(RAND()) -> 1.7656908 | AQ15: =SQRT(Inputs!$B$38)*J15+SQRT(1-Inputs!$B$38)*_xlfn.NORM.S.INV(RAND()) -> -0.13764071 | ... AT15: =SQRT(Inputs!$B$38)*M15+SQRT(1-Inputs!$B$38)*_xlfn.NORM.S.INV(RAND()) -> 0.57391158 | AU15: =Inputs!$B$6*EXP($B$8-0.5*C$5^2+C$5*N15) -> 6137.9517 | AV15: =AU15*EXP($B$8-0.5*D$5^2+D$5*O15) -> 7556.1189 | AW15: =AV15*EXP($B$8-0.5*E$5^2+E$5*P15) -> 8591.0557 | AX15: =AW15*EXP($B$8-0.5*F$5^2+F$5*Q15) -> 10824.928 | AY15: =AX15*EXP($B$8-0.5*G$5^2+G$5*R15) -> 11319.143 | AZ15: =AY15*EXP($B$8-0.5*H$5^2+H$5*S15) -> 11410.837 | BA15: =AZ15*EXP($B$8-0.5*I$5^2+I$5*T15) -> 15430.236 | BB15: =BA15*EXP($B$8-0.5*J$5^2+J$5*U15) -> 19024.807 | BC15: =BB15*EXP($B$8-0.5*K$5^2+K$5*V15) -> 22569.268 | ... BE15: =BD15*EXP($B$8-0.5*M$5^2+M$5*X15) -> 33026.803 | BF15: =Inputs!$B$13*EXP($B$9-0.5*C$6^2+C$6*Y15) -> 16912.46 | BG15: =BF15*EXP($B$9-0.5*D$6^2+D$6*Z15) -> 16221.526 | BH15: =BG15*EXP($B$9-0.5*E$6^2+E$6*AA15) -> 23391.609 | BI15: =BH15*EXP($B$9-0.5*F$6^2+F$6*AB15) -> 37081.503 | BJ15: =BI15*EXP($B$9-0.5*G$6^2+G$6*AC15) -> 41518.014 | BK15: =BJ15*EXP($B$9-0.5*H$6^2+H$6*AD15) -> 42482.28 | BL15: =BK15*EXP($B$9-0.5*I$6^2+I$6*AE15) -> 56809.319 | BM15: =BL15*EXP($B$9-0.5*J$6^2+J$6*AF15) -> 74827.64 | BN15: =BM15*EXP($B$9-0.5*K$6^2+K$6*AG15) -> 87359.847 | ... BP15: =BO15*EXP($B$9-0.5*M$6^2+M$6*AI15) -> 141524.21 | BQ15: =Inputs!$B$20*EXP($B$10-0.5*C$7^2+C$7*AJ15) -> 4803.1542 | BR15: =BQ15*EXP($B$10-0.5*D$7^2+D$7*AK15) -> 5800.6854 | BS15: =BR15*EXP($B$10-0.5*E$7^2+E$7*AL15) -> 6268.5733 | BT15: =BS15*EXP($B$10-0.5*F$7^2+F$7*AM15) -> 6249.7116 | BU15: =BT15*EXP($B$10-0.5*G$7^2+G$7*AN15) -> 11323.151 | BV15: =BU15*EXP($B$10-0.5*H$7^2+H$7*AO15) -> 9972.8155 | BW15: =BV15*EXP($B$10-0.5*I$7^2+I$7*AP15) -> 20222.228 | BX15: =BW15*EXP($B$10-0.5*J$7^2+J$7*AQ15) -> 27514.252 | BY15: =BX15*EXP($B$10-0.5*K$7^2+K$7*AR15) -> 49902.241 | ... CA15: =BZ15*EXP($B$10-0.5*M$7^2+M$7*AT15) -> 113425.31 | CB15: =(AU15*DCF!C$10-DCF!C$5*MAX(AU15*DCF!C$10,0)-MAX(AU15-Inputs!$B$6,0)/Inputs!$B$10)*DCF!C$6 -> 1034.6913 | CC15: =(AV15*DCF!D$10-DCF!D$5*MAX(AV15*DCF!D$10,0)-MAX(AV15-AU15,0)/Inputs!$B$10)*DCF!D$6 -> 1495.9698 | CD15: =(AW15*DCF!E$10-DCF!E$5*MAX(AW15*DCF!E$10,0)-MAX(AW15-AV15,0)/Inputs!$B$10)*DCF!E$6 -> 1750.4274 | CE15: =(AX15*DCF!F$10-DCF!F$5*MAX(AX15*DCF!F$10,0)-MAX(AX15-AW15,0)/Inputs!$B$10)*DCF!F$6 -> 1898.2511 | CF15: =(AY15*DCF!G$10-DCF!G$5*MAX(AY15*DCF!G$10,0)-MAX(AY15-AX15,0)/Inputs!$B$10)*DCF!G$6 -> 2237.1979 | CG15: =(AZ15*DCF!H$10-DCF!H$5*MAX(AZ15*DCF!H$10,0)-MAX(AZ15-AY15,0)/Inputs!$B$10)*DCF!H$6 -> 2199.1402 | CH15: =(BA15*DCF!I$10-DCF!I$5*MAX(BA15*DCF!I$10,0)-MAX(BA15-AZ15,0)/Inputs!$B$10)*DCF!I$6 -> 2159.2189 | CI15: =(BB15*DCF!J$10-DCF!J$5*MAX(BB15*DCF!J$10,0)-MAX(BB15-BA15,0)/Inputs!$B$10)*DCF!J$6 -> 2720.003 | CJ15: =(BC15*DCF!K$10-DCF!K$5*MAX(BC15*DCF!K$10,0)-MAX(BC15-BB15,0)/Inputs!$B$10)*DCF!K$6 -> 3137.1191 | ... CL15: =(BE15*DCF!M$10-DCF!M$5*MAX(BE15*DCF!M$10,0)-MAX(BE15-BD15,0)/Inputs!$B$10)*DCF!M$6 -> 3759.342 | CM15: =(BF15*DCF!C$28-DCF!C$5*MAX(BF15*DCF!C$28,0)-MAX(BF15-Inputs!$B$13,0)/Inputs!$B$17)*DCF!C$6 -> 3885.4841 | CN15: =(BG15*DCF!D$28-DCF!D$5*MAX(BG15*DCF!D$28,0)-MAX(BG15-BF15,0)/Inputs!$B$17)*DCF!D$6 -> 4777.6137 | CO15: =(BH15*DCF!E$28-DCF!E$5*MAX(BH15*DCF!E$28,0)-MAX(BH15-BG15,0)/Inputs!$B$17)*DCF!E$6 -> 5211.7956 | CP15: =(BI15*DCF!F$28-DCF!F$5*MAX(BI15*DCF!F$28,0)-MAX(BI15-BH15,0)/Inputs!$B$17)*DCF!F$6 -> 7574.1897 | CQ15: =(BJ15*DCF!G$28-DCF!G$5*MAX(BJ15*DCF!G$28,0)-MAX(BJ15-BI15,0)/Inputs!$B$17)*DCF!G$6 -> 10025.986 | CR15: =(BK15*DCF!H$28-DCF!H$5*MAX(BK15*DCF!H$28,0)-MAX(BK15-BJ15,0)/Inputs!$B$17)*DCF!H$6 -> 10356.517 | CS15: =(BL15*DCF!I$28-DCF!I$5*MAX(BL15*DCF!I$28,0)-MAX(BL15-BK15,0)/Inputs!$B$17)*DCF!I$6 -> 11302.515 | CT15: =(BM15*DCF!J$28-DCF!J$5*MAX(BM15*DCF!J$28,0)-MAX(BM15-BL15,0)/Inputs!$B$17)*DCF!J$6 -> 14303.694 | CU15: =(BN15*DCF!K$28-DCF!K$5*MAX(BN15*DCF!K$28,0)-MAX(BN15-BM15,0)/Inputs!$B$17)*DCF!K$6 -> 16913.907 | ... CW15: =(BP15*DCF!M$28-DCF!M$5*MAX(BP15*DCF!M$28,0)-MAX(BP15-BO15,0)/Inputs!$B$17)*DCF!M$6 -> 23221.798 | CX15: =(BQ15*DCF!C$46-DCF!C$5*MAX(BQ15*DCF!C$46,0)-MAX(BQ15-Inputs!$B$20,0)/Inputs!$B$24)*DCF!C$6 -> -1849.2985 | CY15: =(BR15*DCF!D$46-DCF!D$5*MAX(BR15*DCF!D$46,0)-MAX(BR15-BQ15,0)/Inputs!$B$24)*DCF!D$6 -> -1415.68 | CZ15: =(BS15*DCF!E$46-DCF!E$5*MAX(BS15*DCF!E$46,0)-MAX(BS15-BR15,0)/Inputs!$B$24)*DCF!E$6 -> -925.69824 | DA15: =(BT15*DCF!F$46-DCF!F$5*MAX(BT15*DCF!F$46,0)-MAX(BT15-BS15,0)/Inputs!$B$24)*DCF!F$6 -> -455.14351 | DB15: =(BU15*DCF!G$46-DCF!G$5*MAX(BU15*DCF!G$46,0)-MAX(BU15-BT15,0)/Inputs!$B$24)*DCF!G$6 -> -2087.4933 | DC15: =(BV15*DCF!H$46-DCF!H$5*MAX(BV15*DCF!H$46,0)-MAX(BV15-BU15,0)/Inputs!$B$24)*DCF!H$6 -> 0 | DD15: =(BW15*DCF!I$46-DCF!I$5*MAX(BW15*DCF!I$46,0)-MAX(BW15-BV15,0)/Inputs!$B$24)*DCF!I$6 -> -2475.1697 | DE15: =(BX15*DCF!J$46-DCF!J$5*MAX(BX15*DCF!J$46,0)-MAX(BX15-BW15,0)/Inputs!$B$24)*DCF!J$6 -> -779.57876 | DF15: =(BY15*DCF!K$46-DCF!K$5*MAX(BY15*DCF!K$46,0)-MAX(BY15-BX15,0)/Inputs!$B$24)*DCF!K$6 -> -2633.8786 | ... DH15: =(CA15*DCF!M$46-DCF!M$5*MAX(CA15*DCF!M$46,0)-MAX(CA15-BZ15,0)/Inputs!$B$24)*DCF!M$6 -> 423.84406 | DI15: =SUM(CB15:CL15)+BE15*DCF!M$10*(1+Inputs!$B$30)*(1-Inputs!$B$33)*(1-Inputs!$B$30/Inputs!$B$31)/(Inputs!$B$29-Inputs!$B$30)*DCF!M$6 -> 117771.92 | DJ15: =SUM(CM15:CW15)+BP15*DCF!M$28*(1+Inputs!$B$30)*(1-Inputs!$B$33)*(1-Inputs!$B$30/Inputs!$B$31)/(Inputs!$B$29-Inputs!$B$30)*DCF!M$6 -> 652019.06 | DK15: =SUM(CX15:DH15)+CA15*DCF!M$46*(1+Inputs!$B$30)*(1-Inputs!$B$33)*(1-Inputs!$B$30/Inputs!$B$31)/(Inputs!$B$29-Inputs!$B$30)*DCF!M$6 -> 163002.77 | DM15: =DI15+DJ15+DK15+Inputs!$B$34+Inputs!$B$36-Inputs!$B$35 -> 1009644.8
A16: 3 | C16: =_xlfn.NORM.S.INV(RAND()) -> -1.5444695 | D16: =_xlfn.NORM.S.INV(RAND()) -> -0.2740138 | E16: =_xlfn.NORM.S.INV(RAND()) -> -0.26960314 | F16: =_xlfn.NORM.S.INV(RAND()) -> -0.92858525 | G16: =_xlfn.NORM.S.INV(RAND()) -> -0.49987716 | H16: =_xlfn.NORM.S.INV(RAND()) -> 0.12662781 | I16: =_xlfn.NORM.S.INV(RAND()) -> -1.7655709 | J16: =_xlfn.NORM.S.INV(RAND()) -> -1.567023 | ... M16: =_xlfn.NORM.S.INV(RAND()) -> -1.9434072 | N16: =SQRT(Inputs!$B$38)*C16+SQRT(1-Inputs!$B$38)*_xlfn.NORM.S.INV(RAND()) -> -0.8736558 | O16: =SQRT(Inputs!$B$38)*D16+SQRT(1-Inputs!$B$38)*_xlfn.NORM.S.INV(RAND()) -> -0.78040726 | P16: =SQRT(Inputs!$B$38)*E16+SQRT(1-Inputs!$B$38)*_xlfn.NORM.S.INV(RAND()) -> 0.56077767 | Q16: =SQRT(Inputs!$B$38)*F16+SQRT(1-Inputs!$B$38)*_xlfn.NORM.S.INV(RAND()) -> -1.365717 | R16: =SQRT(Inputs!$B$38)*G16+SQRT(1-Inputs!$B$38)*_xlfn.NORM.S.INV(RAND()) -> 0.35775847 | S16: =SQRT(Inputs!$B$38)*H16+SQRT(1-Inputs!$B$38)*_xlfn.NORM.S.INV(RAND()) -> 0.41322574 | T16: =SQRT(Inputs!$B$38)*I16+SQRT(1-Inputs!$B$38)*_xlfn.NORM.S.INV(RAND()) -> -1.5592541 | U16: =SQRT(Inputs!$B$38)*J16+SQRT(1-Inputs!$B$38)*_xlfn.NORM.S.INV(RAND()) -> -0.42419783 | ... X16: =SQRT(Inputs!$B$38)*M16+SQRT(1-Inputs!$B$38)*_xlfn.NORM.S.INV(RAND()) -> -0.67287191 | Y16: =SQRT(Inputs!$B$38)*C16+SQRT(1-Inputs!$B$38)*_xlfn.NORM.S.INV(RAND()) -> -1.6211951 | Z16: =SQRT(Inputs!$B$38)*D16+SQRT(1-Inputs!$B$38)*_xlfn.NORM.S.INV(RAND()) -> 1.662654 | AA16: =SQRT(Inputs!$B$38)*E16+SQRT(1-Inputs!$B$38)*_xlfn.NORM.S.INV(RAND()) -> -0.6676351 | AB16: =SQRT(Inputs!$B$38)*F16+SQRT(1-Inputs!$B$38)*_xlfn.NORM.S.INV(RAND()) -> 0.8920561 | AC16: =SQRT(Inputs!$B$38)*G16+SQRT(1-Inputs!$B$38)*_xlfn.NORM.S.INV(RAND()) -> -0.56228473 | AD16: =SQRT(Inputs!$B$38)*H16+SQRT(1-Inputs!$B$38)*_xlfn.NORM.S.INV(RAND()) -> -0.6614673 | AE16: =SQRT(Inputs!$B$38)*I16+SQRT(1-Inputs!$B$38)*_xlfn.NORM.S.INV(RAND()) -> -0.83280776 | AF16: =SQRT(Inputs!$B$38)*J16+SQRT(1-Inputs!$B$38)*_xlfn.NORM.S.INV(RAND()) -> 0.096398321 | ... AI16: =SQRT(Inputs!$B$38)*M16+SQRT(1-Inputs!$B$38)*_xlfn.NORM.S.INV(RAND()) -> -1.1509788 | AJ16: =SQRT(Inputs!$B$38)*C16+SQRT(1-Inputs!$B$38)*_xlfn.NORM.S.INV(RAND()) -> -0.060959674 | AK16: =SQRT(Inputs!$B$38)*D16+SQRT(1-Inputs!$B$38)*_xlfn.NORM.S.INV(RAND()) -> 0.85634138 | AL16: =SQRT(Inputs!$B$38)*E16+SQRT(1-Inputs!$B$38)*_xlfn.NORM.S.INV(RAND()) -> -0.50906469 | AM16: =SQRT(Inputs!$B$38)*F16+SQRT(1-Inputs!$B$38)*_xlfn.NORM.S.INV(RAND()) -> -1.0062763 | AN16: =SQRT(Inputs!$B$38)*G16+SQRT(1-Inputs!$B$38)*_xlfn.NORM.S.INV(RAND()) -> -0.78967937 | AO16: =SQRT(Inputs!$B$38)*H16+SQRT(1-Inputs!$B$38)*_xlfn.NORM.S.INV(RAND()) -> -0.43139989 | AP16: =SQRT(Inputs!$B$38)*I16+SQRT(1-Inputs!$B$38)*_xlfn.NORM.S.INV(RAND()) -> -0.5971008 | AQ16: =SQRT(Inputs!$B$38)*J16+SQRT(1-Inputs!$B$38)*_xlfn.NORM.S.INV(RAND()) -> -0.20181332 | ... AT16: =SQRT(Inputs!$B$38)*M16+SQRT(1-Inputs!$B$38)*_xlfn.NORM.S.INV(RAND()) -> -0.016466967 | AU16: =Inputs!$B$6*EXP($B$8-0.5*C$5^2+C$5*N16) -> 4307.8364 | AV16: =AU16*EXP($B$8-0.5*D$5^2+D$5*O16) -> 4675.2088 | AW16: =AV16*EXP($B$8-0.5*E$5^2+E$5*P16) -> 6148.4978 | AX16: =AW16*EXP($B$8-0.5*F$5^2+F$5*Q16) -> 6329.1933 | AY16: =AX16*EXP($B$8-0.5*G$5^2+G$5*R16) -> 8064.9461 | AZ16: =AY16*EXP($B$8-0.5*H$5^2+H$5*S16) -> 10322.853 | BA16: =AZ16*EXP($B$8-0.5*I$5^2+I$5*T16) -> 10730.438 | BB16: =BA16*EXP($B$8-0.5*J$5^2+J$5*U16) -> 12590.685 | BC16: =BB16*EXP($B$8-0.5*K$5^2+K$5*V16) -> 14296.394 | ... BE16: =BD16*EXP($B$8-0.5*M$5^2+M$5*X16) -> 21888.111 | BF16: =Inputs!$B$13*EXP($B$9-0.5*C$6^2+C$6*Y16) -> 10029.35 | BG16: =BF16*EXP($B$9-0.5*D$6^2+D$6*Z16) -> 16499.599 | BH16: =BG16*EXP($B$9-0.5*E$6^2+E$6*AA16) -> 18046.327 | BI16: =BH16*EXP($B$9-0.5*F$6^2+F$6*AB16) -> 25342.785 | BJ16: =BI16*EXP($B$9-0.5*G$6^2+G$6*AC16) -> 28649.813 | BK16: =BJ16*EXP($B$9-0.5*H$6^2+H$6*AD16) -> 32134.099 | BL16: =BK16*EXP($B$9-0.5*I$6^2+I$6*AE16) -> 35434.592 | BM16: =BL16*EXP($B$9-0.5*J$6^2+J$6*AF16) -> 44081.503 | BN16: =BM16*EXP($B$9-0.5*K$6^2+K$6*AG16) -> 47790.28 | ... BP16: =BO16*EXP($B$9-0.5*M$6^2+M$6*AI16) -> 66045.714 | BQ16: =Inputs!$B$20*EXP($B$10-0.5*C$7^2+C$7*AJ16) -> 4197.7643 | BR16: =BQ16*EXP($B$10-0.5*D$7^2+D$7*AK16) -> 7475.9447 | BS16: =BR16*EXP($B$10-0.5*E$7^2+E$7*AL16) -> 8845.0053 | BT16: =BS16*EXP($B$10-0.5*F$7^2+F$7*AM16) -> 9365.8975 | BU16: =BT16*EXP($B$10-0.5*G$7^2+G$7*AN16) -> 10722.367 | BV16: =BU16*EXP($B$10-0.5*H$7^2+H$7*AO16) -> 13536.212 | BW16: =BV16*EXP($B$10-0.5*I$7^2+I$7*AP16) -> 16646.581 | BX16: =BW16*EXP($B$10-0.5*J$7^2+J$7*AQ16) -> 22359.732 | BY16: =BX16*EXP($B$10-0.5*K$7^2+K$7*AR16) -> 36186.975 | ... CA16: =BZ16*EXP($B$10-0.5*M$7^2+M$7*AT16) -> 78812.871 | CB16: =(AU16*DCF!C$10-DCF!C$5*MAX(AU16*DCF!C$10,0)-MAX(AU16-Inputs!$B$6,0)/Inputs!$B$10)*DCF!C$6 -> 1047.7403 | CC16: =(AV16*DCF!D$10-DCF!D$5*MAX(AV16*DCF!D$10,0)-MAX(AV16-AU16,0)/Inputs!$B$10)*DCF!D$6 -> 1049.9763 | CD16: =(AW16*DCF!E$10-DCF!E$5*MAX(AW16*DCF!E$10,0)-MAX(AW16-AV16,0)/Inputs!$B$10)*DCF!E$6 -> 1087.7446 | CE16: =(AX16*DCF!F$10-DCF!F$5*MAX(AX16*DCF!F$10,0)-MAX(AX16-AW16,0)/Inputs!$B$10)*DCF!F$6 -> 1344.0546 | CF16: =(AY16*DCF!G$10-DCF!G$5*MAX(AY16*DCF!G$10,0)-MAX(AY16-AX16,0)/Inputs!$B$10)*DCF!G$6 -> 1328.0586 | CG16: =(AZ16*DCF!H$10-DCF!H$5*MAX(AZ16*DCF!H$10,0)-MAX(AZ16-AY16,0)/Inputs!$B$10)*DCF!H$6 -> 1603.2575 | CH16: =(BA16*DCF!I$10-DCF!I$5*MAX(BA16*DCF!I$10,0)-MAX(BA16-AZ16,0)/Inputs!$B$10)*DCF!I$6 -> 1893.2013 | CI16: =(BB16*DCF!J$10-DCF!J$5*MAX(BB16*DCF!J$10,0)-MAX(BB16-BA16,0)/Inputs!$B$10)*DCF!J$6 -> 1878.7009 | CJ16: =(BC16*DCF!K$10-DCF!K$5*MAX(BC16*DCF!K$10,0)-MAX(BC16-BB16,0)/Inputs!$B$10)*DCF!K$6 -> 2062.7165 | ... CL16: =(BE16*DCF!M$10-DCF!M$5*MAX(BE16*DCF!M$10,0)-MAX(BE16-BD16,0)/Inputs!$B$10)*DCF!M$6 -> 2742.649 | CM16: =(BF16*DCF!C$28-DCF!C$5*MAX(BF16*DCF!C$28,0)-MAX(BF16-Inputs!$B$13,0)/Inputs!$B$17)*DCF!C$6 -> 3060.8918 | CN16: =(BG16*DCF!D$28-DCF!D$5*MAX(BG16*DCF!D$28,0)-MAX(BG16-BF16,0)/Inputs!$B$17)*DCF!D$6 -> 3479.1116 | CO16: =(BH16*DCF!E$28-DCF!E$5*MAX(BH16*DCF!E$28,0)-MAX(BH16-BG16,0)/Inputs!$B$17)*DCF!E$6 -> 4806.2023 | CP16: =(BI16*DCF!F$28-DCF!F$5*MAX(BI16*DCF!F$28,0)-MAX(BI16-BH16,0)/Inputs!$B$17)*DCF!F$6 -> 5551.463 | CQ16: =(BJ16*DCF!G$28-DCF!G$5*MAX(BJ16*DCF!G$28,0)-MAX(BJ16-BI16,0)/Inputs!$B$17)*DCF!G$6 -> 6877.2019 | CR16: =(BK16*DCF!H$28-DCF!H$5*MAX(BK16*DCF!H$28,0)-MAX(BK16-BJ16,0)/Inputs!$B$17)*DCF!H$6 -> 7405.757 | CS16: =(BL16*DCF!I$28-DCF!I$5*MAX(BL16*DCF!I$28,0)-MAX(BL16-BK16,0)/Inputs!$B$17)*DCF!I$6 -> 7858.83 | CT16: =(BM16*DCF!J$28-DCF!J$5*MAX(BM16*DCF!J$28,0)-MAX(BM16-BL16,0)/Inputs!$B$17)*DCF!J$6 -> 8687.3249 | CU16: =(BN16*DCF!K$28-DCF!K$5*MAX(BN16*DCF!K$28,0)-MAX(BN16-BM16,0)/Inputs!$B$17)*DCF!K$6 -> 9638.2301 | ... CW16: =(BP16*DCF!M$28-DCF!M$5*MAX(BP16*DCF!M$28,0)-MAX(BP16-BO16,0)/Inputs!$B$17)*DCF!M$6 -> 11913.166 | CX16: =(BQ16*DCF!C$46-DCF!C$5*MAX(BQ16*DCF!C$46,0)-MAX(BQ16-Inputs!$B$20,0)/Inputs!$B$24)*DCF!C$6 -> -1429.8598 | CY16: =(BR16*DCF!D$46-DCF!D$5*MAX(BR16*DCF!D$46,0)-MAX(BR16-BQ16,0)/Inputs!$B$24)*DCF!D$6 -> -2674.7418 | CZ16: =(BS16*DCF!E$46-DCF!E$5*MAX(BS16*DCF!E$46,0)-MAX(BS16-BR16,0)/Inputs!$B$24)*DCF!E$6 -> -1585.5833 | DA16: =(BT16*DCF!F$46-DCF!F$5*MAX(BT16*DCF!F$46,0)-MAX(BT16-BS16,0)/Inputs!$B$24)*DCF!F$6 -> -871.75718 | DB16: =(BU16*DCF!G$46-DCF!G$5*MAX(BU16*DCF!G$46,0)-MAX(BU16-BT16,0)/Inputs!$B$24)*DCF!G$6 -> -816.96866 | DC16: =(BV16*DCF!H$46-DCF!H$5*MAX(BV16*DCF!H$46,0)-MAX(BV16-BU16,0)/Inputs!$B$24)*DCF!H$6 -> -874.38518 | DD16: =(BW16*DCF!I$46-DCF!I$5*MAX(BW16*DCF!I$46,0)-MAX(BW16-BV16,0)/Inputs!$B$24)*DCF!I$6 -> -508.40752 | DE16: =(BX16*DCF!J$46-DCF!J$5*MAX(BX16*DCF!J$46,0)-MAX(BX16-BW16,0)/Inputs!$B$24)*DCF!J$6 -> -577.10517 | DF16: =(BY16*DCF!K$46-DCF!K$5*MAX(BY16*DCF!K$46,0)-MAX(BY16-BX16,0)/Inputs!$B$24)*DCF!K$6 -> -1320.1856 | ... DH16: =(CA16*DCF!M$46-DCF!M$5*MAX(CA16*DCF!M$46,0)-MAX(CA16-BZ16,0)/Inputs!$B$24)*DCF!M$6 -> 1466.1247 | DI16: =SUM(CB16:CL16)+BE16*DCF!M$10*(1+Inputs!$B$30)*(1-Inputs!$B$33)*(1-Inputs!$B$30/Inputs!$B$31)/(Inputs!$B$29-Inputs!$B$30)*DCF!M$6 -> 79210.124 | DJ16: =SUM(CM16:CW16)+BP16*DCF!M$28*(1+Inputs!$B$30)*(1-Inputs!$B$33)*(1-Inputs!$B$30/Inputs!$B$31)/(Inputs!$B$29-Inputs!$B$30)*DCF!M$6 -> 325040.66 | DK16: =SUM(CX16:DH16)+CA16*DCF!M$46*(1+Inputs!$B$30)*(1-Inputs!$B$33)*(1-Inputs!$B$30/Inputs!$B$31)/(Inputs!$B$29-Inputs!$B$30)*DCF!M$6 -> 112005.82 | DM16: =DI16+DJ16+DK16+Inputs!$B$34+Inputs!$B$36-Inputs!$B$35 -> 593107.6
A17: 4 | C17: =_xlfn.NORM.S.INV(RAND()) -> 0.52642688 | D17: =_xlfn.NORM.S.INV(RAND()) -> -0.43621225 | E17: =_xlfn.NORM.S.INV(RAND()) -> 0.23700693 | F17: =_xlfn.NORM.S.INV(RAND()) -> -0.36997229 | G17: =_xlfn.NORM.S.INV(RAND()) -> 0.19689505 | H17: =_xlfn.NORM.S.INV(RAND()) -> -0.53204403 | I17: =_xlfn.NORM.S.INV(RAND()) -> 1.1039546 | J17: =_xlfn.NORM.S.INV(RAND()) -> 0.15101838 | ... M17: =_xlfn.NORM.S.INV(RAND()) -> 0.14923249 | N17: =SQRT(Inputs!$B$38)*C17+SQRT(1-Inputs!$B$38)*_xlfn.NORM.S.INV(RAND()) -> 0.47074689 | O17: =SQRT(Inputs!$B$38)*D17+SQRT(1-Inputs!$B$38)*_xlfn.NORM.S.INV(RAND()) -> 0.89908794 | P17: =SQRT(Inputs!$B$38)*E17+SQRT(1-Inputs!$B$38)*_xlfn.NORM.S.INV(RAND()) -> 0.88501621 | Q17: =SQRT(Inputs!$B$38)*F17+SQRT(1-Inputs!$B$38)*_xlfn.NORM.S.INV(RAND()) -> -0.33383682 | R17: =SQRT(Inputs!$B$38)*G17+SQRT(1-Inputs!$B$38)*_xlfn.NORM.S.INV(RAND()) -> 0.95646507 | S17: =SQRT(Inputs!$B$38)*H17+SQRT(1-Inputs!$B$38)*_xlfn.NORM.S.INV(RAND()) -> -1.4449946 | T17: =SQRT(Inputs!$B$38)*I17+SQRT(1-Inputs!$B$38)*_xlfn.NORM.S.INV(RAND()) -> 0.59709862 | U17: =SQRT(Inputs!$B$38)*J17+SQRT(1-Inputs!$B$38)*_xlfn.NORM.S.INV(RAND()) -> 0.31425183 | ... X17: =SQRT(Inputs!$B$38)*M17+SQRT(1-Inputs!$B$38)*_xlfn.NORM.S.INV(RAND()) -> -1.3259054 | Y17: =SQRT(Inputs!$B$38)*C17+SQRT(1-Inputs!$B$38)*_xlfn.NORM.S.INV(RAND()) -> 1.0875984 | Z17: =SQRT(Inputs!$B$38)*D17+SQRT(1-Inputs!$B$38)*_xlfn.NORM.S.INV(RAND()) -> 0.05843651 | AA17: =SQRT(Inputs!$B$38)*E17+SQRT(1-Inputs!$B$38)*_xlfn.NORM.S.INV(RAND()) -> 0.31934954 | AB17: =SQRT(Inputs!$B$38)*F17+SQRT(1-Inputs!$B$38)*_xlfn.NORM.S.INV(RAND()) -> -0.94623594 | AC17: =SQRT(Inputs!$B$38)*G17+SQRT(1-Inputs!$B$38)*_xlfn.NORM.S.INV(RAND()) -> -0.27796009 | AD17: =SQRT(Inputs!$B$38)*H17+SQRT(1-Inputs!$B$38)*_xlfn.NORM.S.INV(RAND()) -> -0.1950446 | AE17: =SQRT(Inputs!$B$38)*I17+SQRT(1-Inputs!$B$38)*_xlfn.NORM.S.INV(RAND()) -> 1.2227755 | AF17: =SQRT(Inputs!$B$38)*J17+SQRT(1-Inputs!$B$38)*_xlfn.NORM.S.INV(RAND()) -> 0.06072093 | ... AI17: =SQRT(Inputs!$B$38)*M17+SQRT(1-Inputs!$B$38)*_xlfn.NORM.S.INV(RAND()) -> 1.0179344 | AJ17: =SQRT(Inputs!$B$38)*C17+SQRT(1-Inputs!$B$38)*_xlfn.NORM.S.INV(RAND()) -> -0.29206539 | AK17: =SQRT(Inputs!$B$38)*D17+SQRT(1-Inputs!$B$38)*_xlfn.NORM.S.INV(RAND()) -> 0.21835061 | AL17: =SQRT(Inputs!$B$38)*E17+SQRT(1-Inputs!$B$38)*_xlfn.NORM.S.INV(RAND()) -> 1.6735184 | AM17: =SQRT(Inputs!$B$38)*F17+SQRT(1-Inputs!$B$38)*_xlfn.NORM.S.INV(RAND()) -> -0.10957886 | AN17: =SQRT(Inputs!$B$38)*G17+SQRT(1-Inputs!$B$38)*_xlfn.NORM.S.INV(RAND()) -> 0.25035469 | AO17: =SQRT(Inputs!$B$38)*H17+SQRT(1-Inputs!$B$38)*_xlfn.NORM.S.INV(RAND()) -> -1.4072554 | AP17: =SQRT(Inputs!$B$38)*I17+SQRT(1-Inputs!$B$38)*_xlfn.NORM.S.INV(RAND()) -> 2.7207749 | AQ17: =SQRT(Inputs!$B$38)*J17+SQRT(1-Inputs!$B$38)*_xlfn.NORM.S.INV(RAND()) -> 0.41230261 | ... AT17: =SQRT(Inputs!$B$38)*M17+SQRT(1-Inputs!$B$38)*_xlfn.NORM.S.INV(RAND()) -> -0.65644694 | AU17: =Inputs!$B$6*EXP($B$8-0.5*C$5^2+C$5*N17) -> 5355.1482 | AV17: =AU17*EXP($B$8-0.5*D$5^2+D$5*O17) -> 7439.7405 | AW17: =AV17*EXP($B$8-0.5*E$5^2+E$5*P17) -> 10221.605 | AX17: =AW17*EXP($B$8-0.5*F$5^2+F$5*Q17) -> 11969.771 | AY17: =AX17*EXP($B$8-0.5*G$5^2+G$5*R17) -> 16357.072 | AZ17: =AY17*EXP($B$8-0.5*H$5^2+H$5*S17) -> 17062.231 | BA17: =AZ17*EXP($B$8-0.5*I$5^2+I$5*T17) -> 22226.266 | BB17: =BA17*EXP($B$8-0.5*J$5^2+J$5*U17) -> 28082.107 | BC17: =BB17*EXP($B$8-0.5*K$5^2+K$5*V17) -> 29499.842 | ... BE17: =BD17*EXP($B$8-0.5*M$5^2+M$5*X17) -> 33146.629 | BF17: =Inputs!$B$13*EXP($B$9-0.5*C$6^2+C$6*Y17) -> 17159.086 | BG17: =BF17*EXP($B$9-0.5*D$6^2+D$6*Z17) -> 21134.054 | BH17: =BG17*EXP($B$9-0.5*E$6^2+E$6*AA17) -> 27226.493 | BI17: =BH17*EXP($B$9-0.5*F$6^2+F$6*AB17) -> 28812.042 | BJ17: =BI17*EXP($B$9-0.5*G$6^2+G$6*AC17) -> 33934.44 | BK17: =BJ17*EXP($B$9-0.5*H$6^2+H$6*AD17) -> 40556.724 | BL17: =BK17*EXP($B$9-0.5*I$6^2+I$6*AE17) -> 58373.308 | BM17: =BL17*EXP($B$9-0.5*J$6^2+J$6*AF17) -> 72296.692 | BN17: =BM17*EXP($B$9-0.5*K$6^2+K$6*AG17) -> 75596.466 | ... BP17: =BO17*EXP($B$9-0.5*M$6^2+M$6*AI17) -> 125986.15 | BQ17: =Inputs!$B$20*EXP($B$10-0.5*C$7^2+C$7*AJ17) -> 3867.4016 | BR17: =BQ17*EXP($B$10-0.5*D$7^2+D$7*AK17) -> 5624.3657 | BS17: =BR17*EXP($B$10-0.5*E$7^2+E$7*AL17) -> 12454.909 | BT17: =BS17*EXP($B$10-0.5*F$7^2+F$7*AM17) -> 16685.994 | BU17: =BT17*EXP($B$10-0.5*G$7^2+G$7*AN17) -> 24568.947 | BV17: =BU17*EXP($B$10-0.5*H$7^2+H$7*AO17) -> 24894.852 | BW17: =BV17*EXP($B$10-0.5*I$7^2+I$7*AP17) -> 61788.876 | BX17: =BW17*EXP($B$10-0.5*J$7^2+J$7*AQ17) -> 93868.463 | BY17: =BX17*EXP($B$10-0.5*K$7^2+K$7*AR17) -> 125708.43 | ... CA17: =BZ17*EXP($B$10-0.5*M$7^2+M$7*AT17) -> 167025.14 | CB17: =(AU17*DCF!C$10-DCF!C$5*MAX(AU17*DCF!C$10,0)-MAX(AU17-Inputs!$B$6,0)/Inputs!$B$10)*DCF!C$6 -> 1040.2728 | CC17: =(AV17*DCF!D$10-DCF!D$5*MAX(AV17*DCF!D$10,0)-MAX(AV17-AU17,0)/Inputs!$B$10)*DCF!D$6 -> 1305.1131 | CD17: =(AW17*DCF!E$10-DCF!E$5*MAX(AW17*DCF!E$10,0)-MAX(AW17-AV17,0)/Inputs!$B$10)*DCF!E$6 -> 1733.4148 | CE17: =(AX17*DCF!F$10-DCF!F$5*MAX(AX17*DCF!F$10,0)-MAX(AX17-AW17,0)/Inputs!$B$10)*DCF!F$6 -> 2249.2319 | CF17: =(AY17*DCF!G$10-DCF!G$5*MAX(AY17*DCF!G$10,0)-MAX(AY17-AX17,0)/Inputs!$B$10)*DCF!G$6 -> 2526.8935 | CG17: =(AZ17*DCF!H$10-DCF!H$5*MAX(AZ17*DCF!H$10,0)-MAX(AZ17-AY17,0)/Inputs!$B$10)*DCF!H$6 -> 3187.4308 | CH17: =(BA17*DCF!I$10-DCF!I$5*MAX(BA17*DCF!I$10,0)-MAX(BA17-AZ17,0)/Inputs!$B$10)*DCF!I$6 -> 3212.8454 | CI17: =(BB17*DCF!J$10-DCF!J$5*MAX(BB17*DCF!J$10,0)-MAX(BB17-BA17,0)/Inputs!$B$10)*DCF!J$6 -> 3931.5985 | CJ17: =(BC17*DCF!K$10-DCF!K$5*MAX(BC17*DCF!K$10,0)-MAX(BC17-BB17,0)/Inputs!$B$10)*DCF!K$6 -> 4550.5395 | ... CL17: =(BE17*DCF!M$10-DCF!M$5*MAX(BE17*DCF!M$10,0)-MAX(BE17-BD17,0)/Inputs!$B$10)*DCF!M$6 -> 4363.9251 | CM17: =(BF17*DCF!C$28-DCF!C$5*MAX(BF17*DCF!C$28,0)-MAX(BF17-Inputs!$B$13,0)/Inputs!$B$17)*DCF!C$6 -> 3903.7952 | CN17: =(BG17*DCF!D$28-DCF!D$5*MAX(BG17*DCF!D$28,0)-MAX(BG17-BF17,0)/Inputs!$B$17)*DCF!D$6 -> 5376.4234 | CO17: =(BH17*DCF!E$28-DCF!E$5*MAX(BH17*DCF!E$28,0)-MAX(BH17-BG17,0)/Inputs!$B$17)*DCF!E$6 -> 6510.2918 | CP17: =(BI17*DCF!F$28-DCF!F$5*MAX(BI17*DCF!F$28,0)-MAX(BI17-BH17,0)/Inputs!$B$17)*DCF!F$6 -> 7533.0362 | CQ17: =(BJ17*DCF!G$28-DCF!G$5*MAX(BJ17*DCF!G$28,0)-MAX(BJ17-BI17,0)/Inputs!$B$17)*DCF!G$6 -> 7943.0112 | CR17: =(BK17*DCF!H$28-DCF!H$5*MAX(BK17*DCF!H$28,0)-MAX(BK17-BJ17,0)/Inputs!$B$17)*DCF!H$6 -> 9001.2082 | CS17: =(BL17*DCF!I$28-DCF!I$5*MAX(BL17*DCF!I$28,0)-MAX(BL17-BK17,0)/Inputs!$B$17)*DCF!I$6 -> 11169.435 | CT17: =(BM17*DCF!J$28-DCF!J$5*MAX(BM17*DCF!J$28,0)-MAX(BM17-BL17,0)/Inputs!$B$17)*DCF!J$6 -> 14282.037 | CU17: =(BN17*DCF!K$28-DCF!K$5*MAX(BN17*DCF!K$28,0)-MAX(BN17-BM17,0)/Inputs!$B$17)*DCF!K$6 -> 15560.528 | ... CW17: =(BP17*DCF!M$28-DCF!M$5*MAX(BP17*DCF!M$28,0)-MAX(BP17-BO17,0)/Inputs!$B$17)*DCF!M$6 -> 20069.326 | CX17: =(BQ17*DCF!C$46-DCF!C$5*MAX(BQ17*DCF!C$46,0)-MAX(BQ17-Inputs!$B$20,0)/Inputs!$B$24)*DCF!C$6 -> -1200.9711 | CY17: =(BR17*DCF!D$46-DCF!D$5*MAX(BR17*DCF!D$46,0)-MAX(BR17-BQ17,0)/Inputs!$B$24)*DCF!D$6 -> -1709.63 | CZ17: =(BS17*DCF!E$46-DCF!E$5*MAX(BS17*DCF!E$46,0)-MAX(BS17-BR17,0)/Inputs!$B$24)*DCF!E$6 -> -4165.2267 | DA17: =(BT17*DCF!F$46-DCF!F$5*MAX(BT17*DCF!F$46,0)-MAX(BT17-BS17,0)/Inputs!$B$24)*DCF!F$6 -> -2755.8516 | DB17: =(BU17*DCF!G$46-DCF!G$5*MAX(BU17*DCF!G$46,0)-MAX(BU17-BT17,0)/Inputs!$B$24)*DCF!G$6 -> -3478.1204 | DC17: =(BV17*DCF!H$46-DCF!H$5*MAX(BV17*DCF!H$46,0)-MAX(BV17-BU17,0)/Inputs!$B$24)*DCF!H$6 -> -101.27307 | DD17: =(BW17*DCF!I$46-DCF!I$5*MAX(BW17*DCF!I$46,0)-MAX(BW17-BV17,0)/Inputs!$B$24)*DCF!I$6 -> -9163.8089 | DE17: =(BX17*DCF!J$46-DCF!J$5*MAX(BX17*DCF!J$46,0)-MAX(BX17-BW17,0)/Inputs!$B$24)*DCF!J$6 -> -4569.4599 | DF17: =(BY17*DCF!K$46-DCF!K$5*MAX(BY17*DCF!K$46,0)-MAX(BY17-BX17,0)/Inputs!$B$24)*DCF!K$6 -> -619.05887 | ... DH17: =(CA17*DCF!M$46-DCF!M$5*MAX(CA17*DCF!M$46,0)-MAX(CA17-BZ17,0)/Inputs!$B$24)*DCF!M$6 -> 6109.8449 | DI17: =SUM(CB17:CL17)+BE17*DCF!M$10*(1+Inputs!$B$30)*(1-Inputs!$B$33)*(1-Inputs!$B$30/Inputs!$B$31)/(Inputs!$B$29-Inputs!$B$30)*DCF!M$6 -> 124819.9 | DJ17: =SUM(CM17:CW17)+BP17*DCF!M$28*(1+Inputs!$B$30)*(1-Inputs!$B$33)*(1-Inputs!$B$30/Inputs!$B$31)/(Inputs!$B$29-Inputs!$B$30)*DCF!M$6 -> 585275.58 | DK17: =SUM(CX17:DH17)+CA17*DCF!M$46*(1+Inputs!$B$30)*(1-Inputs!$B$33)*(1-Inputs!$B$30/Inputs!$B$31)/(Inputs!$B$29-Inputs!$B$30)*DCF!M$6 -> 244033.76 | DM17: =DI17+DJ17+DK17+Inputs!$B$34+Inputs!$B$36-Inputs!$B$35 -> 1030980.2
